# 🚨 CORRECTIONS URGENTES - LOGS CELERY
**Date**: 5 octobre 2025  
**Contexte**: Analyse des logs de démarrage Celery - 4 erreurs critiques détectées

---

## ✅ **BON FONCTIONNEMENT GLOBAL**

Le workflow fonctionne de bout en bout :
- ✅ Webhook Monday.com reçu et traité
- ✅ Tâche créée et workflow lancé
- ✅ Environnement Git préparé
- ✅ Analyse requirements effectuée
- ✅ Implémentation réalisée (fichier `main.txt` créé)
- ✅ Tests passés
- ✅ Quality assurance OK
- ✅ PR créée (#8)
- ✅ Validation humaine Monday.com fonctionnelle
- ✅ **Merge réussi** avec commit `9d28ada1...`
- ✅ **Statut Monday.com mis à jour à "Done"** ✨

**Durée totale**: 94 secondes

---

## 🔴 **PROBLÈMES CRITIQUES À CORRIGER**

### **ERREUR 1: HumanValidationRequest - test_results type mismatch**

**📍 Ligne du log**:
```
❌ Erreur lors de la création de validation en DB: 
1 validation error for HumanValidationRequest
test_results
  Input should be a valid dictionary [type=dict_type, input_value=[{'success': True, 'warni...], input_type=list]
```

**🔍 Cause**:
- Le champ `test_results` dans `HumanValidationRequest` attend un `Dict[str, Any]`
- Mais une `List` est fournie depuis `state["results"]["test_results"]`

**📂 Fichier**: `nodes/monday_validation_node.py` ligne ~98

**🛠️ Solution**:
```python
# AVANT (ligne ~98):
test_results=workflow_results.get("test_results"),

# APRÈS:
test_results=_convert_test_results_to_dict(workflow_results.get("test_results")),
```

**Ajouter cette fonction helper** (ligne ~40):
```python
def _convert_test_results_to_dict(test_results) -> Optional[Dict[str, Any]]:
    """
    Convertit test_results en dictionnaire compatible.
    
    Args:
        test_results: Peut être une liste ou un dictionnaire
        
    Returns:
        Dictionnaire structuré ou None
    """
    if not test_results:
        return None
    
    # Si déjà un dict, retourner tel quel
    if isinstance(test_results, dict):
        return test_results
    
    # Si c'est une liste, convertir en dict avec index
    if isinstance(test_results, list):
        return {
            "tests": test_results,
            "count": len(test_results),
            "summary": f"{len(test_results)} test(s) exécuté(s)"
        }
    
    # Fallback: encapsuler dans un dict
    return {"raw": test_results}
```

---

### **ERREUR 2: Settings - db_host attribute manquant**

**📍 Ligne du log**:
```
❌ Erreur initialisation pool DB: 'Settings' object has no attribute 'db_host'
❌ Erreur sauvegarde réponse validation en DB: 'Settings' object has no attribute 'db_host'
```

**🔍 Cause**:
- Code essaie d'accéder à `settings.db_host` qui n'existe pas
- La config utilise `database_url` (chaîne complète) au lieu de composants séparés

**📂 Fichier**: Chercher où `settings.db_host` est utilisé

**🔎 Recherche nécessaire**:
```bash
grep -r "db_host" --include="*.py" .
```

**🛠️ Solution 1 - Ajouter des propriétés dans settings.py** (lignes ~95):
```python
@property
def db_host(self) -> str:
    """Extrait le host de database_url."""
    # Format: postgresql://user:pass@host:port/dbname
    import re
    match = re.search(r'@([^:]+):', self.database_url)
    return match.group(1) if match else "localhost"

@property
def db_port(self) -> int:
    """Extrait le port de database_url."""
    import re
    match = re.search(r':(\d+)/', self.database_url)
    return int(match.group(1)) if match else 5432

@property
def db_name(self) -> str:
    """Extrait le nom de DB de database_url."""
    import re
    match = re.search(r'/([^?]+)(?:\?|$)', self.database_url)
    return match.group(1) if match else "ai_agent_admin"

@property
def db_user(self) -> str:
    """Extrait le user de database_url."""
    import re
    match = re.search(r'://([^:]+):', self.database_url)
    return match.group(1) if match else "admin"

@property
def db_password(self) -> str:
    """Extrait le password de database_url."""
    import re
    match = re.search(r':([^@]+)@', self.database_url)
    return match.group(1) if match else "password"
```

**🛠️ Solution 2 - Corriger les fichiers utilisant db_host**:
Remplacer `settings.db_host` par `settings.db_host` (avec la propriété ci-dessus)

---

### **ERREUR 3: HumanValidationResponse - validation_id None**

**📍 Ligne du log**:
```
❌ Erreur analyse intelligente: 
1 validation error for HumanValidationResponse
validation_id
  Input should be a valid string [type=string_type, input_value=None, input_type=NoneType]
```

**🔍 Cause**:
- L'analyse intelligente crée un `HumanValidationResponse` sans `validation_id`
- Le champ `validation_id` est requis mais reçoit `None`

**📂 Fichier**: Chercher où `HumanValidationResponse` est instancié

**🔎 Recherche**:
```bash
grep -n "HumanValidationResponse(" nodes/monday_validation_node.py services/human_validation_service.py
```

**🛠️ Solution**:
Dans le fichier où l'analyse intelligente est faite, s'assurer que `validation_id` est toujours fourni:

```python
# CHERCHER ce pattern:
HumanValidationResponse(
    # ...
    # validation_id manquant ou None
)

# CORRIGER avec:
HumanValidationResponse(
    validation_id=validation_id or f"validation_{int(time.time())}",  # Générer si absent
    # ... autres champs
)
```

---

### **ERREUR 4: Pydantic Serialization Warnings (NON-CRITIQUE mais RÉPÉTITIF)**

**📍 Logs**:
```
UserWarning: Pydantic serializer warnings:
Expected `str` but got `int` - serialized value may not be as expected
```

**🔍 Cause**:
- Des champs Pydantic définis comme `str` reçoivent des `int`
- Probablement `task_id`, `run_id`, etc.

**📂 Fichiers concernés**: `models/schemas.py`

**🛠️ Solution - Ajouter validateurs**:
```python
# Dans les modèles concernés (ex: TaskRequest, GraphState, etc.)
@field_validator('task_id', 'run_id', 'step_id', mode='before')
@classmethod
def convert_ids_to_str(cls, v):
    """Convertit les IDs en string si nécessaire."""
    if v is None:
        return v
    return str(v)
```

Ou modifier les types pour accepter `int` ou `str`:
```python
task_id: Union[str, int] = Field(..., description="ID de la tâche")
```

---

### **AVERTISSEMENT 5: Colonnes Monday.com non identifiées (NON-CRITIQUE)**

**📍 Log**:
```
🔍 DEBUG - Colonnes disponibles dans Monday.com: ['no_id', 'no_id', 'no_id']
```

**🔍 Cause**:
- Les colonnes Monday ne sont pas correctement parsées
- Mais non-bloquant car la description est trouvée via les updates

**📂 Fichier**: `tools/monday_tool.py` ou `services/webhook_service.py`

**🛠️ Solution** (optionnelle):
Vérifier la requête GraphQL qui récupère les colonnes et s'assurer que les IDs sont bien inclus:
```graphql
query {
  items (ids: [$item_id]) {
    id
    name
    column_values {
      id        # ← Vérifier que c'est présent
      title
      text
      value
    }
  }
}
```

---

## 📋 **ORDRE D'APPLICATION DES CORRECTIONS**

### **Phase 1 - Critiques (⏱️ 30 min)**
1. ✅ **ERREUR 1**: Corriger `test_results` dans `monday_validation_node.py`
2. ✅ **ERREUR 2**: Ajouter propriétés `db_host`, `db_port`, etc. dans `settings.py`
3. ✅ **ERREUR 3**: Corriger `validation_id` dans les instanciations `HumanValidationResponse`

### **Phase 2 - Améliorations (⏱️ 20 min)**
4. ⚠️ **ERREUR 4**: Ajouter validateurs Pydantic pour conversions `int → str`
5. 📝 **AVERTISSEMENT 5**: Vérifier requête GraphQL colonnes Monday (optionnel)

### **Phase 3 - Tests (⏱️ 15 min)**
6. Relancer Celery et tester un workflow complet
7. Vérifier que les erreurs ne réapparaissent plus dans les logs
8. Valider la persistance en DB des validations

---

## 🧪 **COMMANDES DE TEST**

```bash
# 1. Arrêter Celery
pkill -f "celery.*worker"

# 2. Appliquer les corrections (voir fichiers ci-dessus)

# 3. Relancer Celery
celery -A services.celery_app worker --loglevel=info

# 4. Surveiller les logs
tail -f logs/workflow.log | grep -E "(❌|⚠️|Erreur|Error)"

# 5. Tester un workflow dans Monday.com
# → Créer une nouvelle tâche et changer son statut

# 6. Vérifier la base de données
psql postgresql://admin:password@localhost:5432/ai_agent_admin -c "SELECT * FROM human_validations ORDER BY created_at DESC LIMIT 5;"
```

---

## ✅ **CHECKLIST DE VALIDATION**

Après corrections, vérifier:

- [ ] Aucune erreur `test_results` type mismatch
- [ ] Aucune erreur `'Settings' object has no attribute 'db_host'`
- [ ] Aucune erreur `validation_id` None
- [ ] Warnings Pydantic réduits/éliminés
- [ ] Validations humaines enregistrées en DB
- [ ] Réponses de validation sauvegardées en DB
- [ ] Workflow complet fonctionne sans erreur

---

## 🎯 **RÉSUMÉ**

**3 erreurs critiques** empêchent la persistance complète des données :
1. Format `test_results` incorrect
2. Propriétés DB manquantes dans Settings
3. `validation_id` manquant dans les réponses

**Impact actuel**: Le workflow fonctionne ✅ mais les validations ne sont pas sauvegardées en DB ⚠️

**Temps estimé corrections**: ~1 heure  
**Priorité**: 🔴 **HAUTE** (perte de traçabilité des validations)

---

## 📚 **FICHIERS À MODIFIER**

1. `nodes/monday_validation_node.py` (lignes ~40 et ~98)
2. `config/settings.py` (lignes ~95 - ajouter propriétés)
3. `services/human_validation_service.py` (rechercher `HumanValidationResponse(`)
4. `models/schemas.py` (ajouter validateurs optionnels)

---

**FIN DU DOCUMENT**
