[2025-09-25 09:23:39] ERROR    [celery.worker.request:643] [MainProcess] Task handler raised error: WorkerLostError('Worker exited prematurely: signal 15 (SIGTERM) Job: 1.')
Traceback (most recent call last):
  File "/Users/stagiaire_vycode/Stage/AI-Agent/venv/lib/python3.12/site-packages/billiard/pool.py", line 1265, in mark_as_worker_lost
    raise WorkerLostError(
billiard.einfo.ExceptionWithTraceback: 
"""
Traceback (most recent call last):
  File "/Users/stagiaire_vycode/Stage/AI-Agent/venv/lib/python3.12/site-packages/celery/worker/worker.py", line 202, in start
    self.blueprint.start(self)
  File "/Users/stagiaire_vycode/Stage/AI-Agent/venv/lib/python3.12/site-packages/celery/bootsteps.py", line 116, in start
    step.start(parent)
  File "/Users/stagiaire_vycode/Stage/AI-Agent/venv/lib/python3.12/site-packages/celery/bootsteps.py", line 365, in start
    return self.obj.start()
           ^^^^^^^^^^^^^^^^
  File "/Users/stagiaire_vycode/Stage/AI-Agent/venv/lib/python3.12/site-packages/celery/worker/consumer/consumer.py", line 340, in start
    blueprint.start(self)
  File "/Users/stagiaire_vycode/Stage/AI-Agent/venv/lib/python3.12/site-packages/celery/bootsteps.py", line 116, in start
    step.start(parent)
  File "/Users/stagiaire_vycode/Stage/AI-Agent/venv/lib/python3.12/site-packages/celery/worker/consumer/consumer.py", line 742, in start
    c.loop(*c.loop_args())
  File "/Users/stagiaire_vycode/Stage/AI-Agent/venv/lib/python3.12/site-packages/celery/worker/loops.py", line 86, in asynloop
    state.maybe_shutdown()
  File "/Users/stagiaire_vycode/Stage/AI-Agent/venv/lib/python3.12/site-packages/celery/worker/state.py", line 93, in maybe_shutdown
    raise WorkerShutdown(should_stop)
celery.exceptions.WorkerShutdown: 0

During handling of the above exception, another exception occurred:

Traceback (most recent call last):
  File "/Users/stagiaire_vycode/Stage/AI-Agent/venv/lib/python3.12/site-packages/billiard/pool.py", line 1265, in mark_as_worker_lost
    raise WorkerLostError(
billiard.exceptions.WorkerLostError: Worker exited prematurely: signal 15 (SIGTERM) Job: 1.
"""
[2025-09-25 10:13:59] ERROR    [celery.worker.request:643] [MainProcess] Task handler raised error: WorkerLostError('Worker exited prematurely: signal 15 (SIGTERM) Job: 1.')
Traceback (most recent call last):
  File "/Users/stagiaire_vycode/Stage/AI-Agent/venv/lib/python3.12/site-packages/billiard/pool.py", line 1265, in mark_as_worker_lost
    raise WorkerLostError(
billiard.einfo.ExceptionWithTraceback: 
"""
Traceback (most recent call last):
  File "/Users/stagiaire_vycode/Stage/AI-Agent/venv/lib/python3.12/site-packages/celery/worker/worker.py", line 202, in start
    self.blueprint.start(self)
  File "/Users/stagiaire_vycode/Stage/AI-Agent/venv/lib/python3.12/site-packages/celery/bootsteps.py", line 116, in start
    step.start(parent)
  File "/Users/stagiaire_vycode/Stage/AI-Agent/venv/lib/python3.12/site-packages/celery/bootsteps.py", line 365, in start
    return self.obj.start()
           ^^^^^^^^^^^^^^^^
  File "/Users/stagiaire_vycode/Stage/AI-Agent/venv/lib/python3.12/site-packages/celery/worker/consumer/consumer.py", line 340, in start
    blueprint.start(self)
  File "/Users/stagiaire_vycode/Stage/AI-Agent/venv/lib/python3.12/site-packages/celery/bootsteps.py", line 116, in start
    step.start(parent)
  File "/Users/stagiaire_vycode/Stage/AI-Agent/venv/lib/python3.12/site-packages/celery/worker/consumer/consumer.py", line 742, in start
    c.loop(*c.loop_args())
  File "/Users/stagiaire_vycode/Stage/AI-Agent/venv/lib/python3.12/site-packages/celery/worker/loops.py", line 86, in asynloop
    state.maybe_shutdown()
  File "/Users/stagiaire_vycode/Stage/AI-Agent/venv/lib/python3.12/site-packages/celery/worker/state.py", line 93, in maybe_shutdown
    raise WorkerShutdown(should_stop)
celery.exceptions.WorkerShutdown: 0

During handling of the above exception, another exception occurred:

Traceback (most recent call last):
  File "/Users/stagiaire_vycode/Stage/AI-Agent/venv/lib/python3.12/site-packages/billiard/pool.py", line 1265, in mark_as_worker_lost
    raise WorkerLostError(
billiard.exceptions.WorkerLostError: Worker exited prematurely: signal 15 (SIGTERM) Job: 1.
"""
[2025-09-25 10:21:56] ERROR    [celery.worker.request:643] [MainProcess] Task handler raised error: WorkerLostError('Worker exited prematurely: signal 15 (SIGTERM) Job: 1.')
Traceback (most recent call last):
  File "/Users/stagiaire_vycode/Stage/AI-Agent/venv/lib/python3.12/site-packages/billiard/pool.py", line 1265, in mark_as_worker_lost
    raise WorkerLostError(
billiard.einfo.ExceptionWithTraceback: 
"""
Traceback (most recent call last):
  File "/Users/stagiaire_vycode/Stage/AI-Agent/venv/lib/python3.12/site-packages/celery/worker/worker.py", line 202, in start
    self.blueprint.start(self)
  File "/Users/stagiaire_vycode/Stage/AI-Agent/venv/lib/python3.12/site-packages/celery/bootsteps.py", line 116, in start
    step.start(parent)
  File "/Users/stagiaire_vycode/Stage/AI-Agent/venv/lib/python3.12/site-packages/celery/bootsteps.py", line 365, in start
    return self.obj.start()
           ^^^^^^^^^^^^^^^^
  File "/Users/stagiaire_vycode/Stage/AI-Agent/venv/lib/python3.12/site-packages/celery/worker/consumer/consumer.py", line 340, in start
    blueprint.start(self)
  File "/Users/stagiaire_vycode/Stage/AI-Agent/venv/lib/python3.12/site-packages/celery/bootsteps.py", line 116, in start
    step.start(parent)
  File "/Users/stagiaire_vycode/Stage/AI-Agent/venv/lib/python3.12/site-packages/celery/worker/consumer/consumer.py", line 742, in start
    c.loop(*c.loop_args())
  File "/Users/stagiaire_vycode/Stage/AI-Agent/venv/lib/python3.12/site-packages/celery/worker/loops.py", line 86, in asynloop
    state.maybe_shutdown()
  File "/Users/stagiaire_vycode/Stage/AI-Agent/venv/lib/python3.12/site-packages/celery/worker/state.py", line 93, in maybe_shutdown
    raise WorkerShutdown(should_stop)
celery.exceptions.WorkerShutdown: 0

During handling of the above exception, another exception occurred:

Traceback (most recent call last):
  File "/Users/stagiaire_vycode/Stage/AI-Agent/venv/lib/python3.12/site-packages/billiard/pool.py", line 1265, in mark_as_worker_lost
    raise WorkerLostError(
billiard.exceptions.WorkerLostError: Worker exited prematurely: signal 15 (SIGTERM) Job: 1.
"""
[2025-09-25 10:51:06] ERROR    [celery.worker.request:643] [MainProcess] Task handler raised error: WorkerLostError('Worker exited prematurely: signal 15 (SIGTERM) Job: 1.')
Traceback (most recent call last):
  File "/Users/stagiaire_vycode/Stage/AI-Agent/venv/lib/python3.12/site-packages/billiard/pool.py", line 1265, in mark_as_worker_lost
    raise WorkerLostError(
billiard.einfo.ExceptionWithTraceback: 
"""
Traceback (most recent call last):
  File "/Users/stagiaire_vycode/Stage/AI-Agent/venv/lib/python3.12/site-packages/celery/worker/worker.py", line 202, in start
    self.blueprint.start(self)
  File "/Users/stagiaire_vycode/Stage/AI-Agent/venv/lib/python3.12/site-packages/celery/bootsteps.py", line 116, in start
    step.start(parent)
  File "/Users/stagiaire_vycode/Stage/AI-Agent/venv/lib/python3.12/site-packages/celery/bootsteps.py", line 365, in start
    return self.obj.start()
           ^^^^^^^^^^^^^^^^
  File "/Users/stagiaire_vycode/Stage/AI-Agent/venv/lib/python3.12/site-packages/celery/worker/consumer/consumer.py", line 340, in start
    blueprint.start(self)
  File "/Users/stagiaire_vycode/Stage/AI-Agent/venv/lib/python3.12/site-packages/celery/bootsteps.py", line 116, in start
    step.start(parent)
  File "/Users/stagiaire_vycode/Stage/AI-Agent/venv/lib/python3.12/site-packages/celery/worker/consumer/consumer.py", line 742, in start
    c.loop(*c.loop_args())
  File "/Users/stagiaire_vycode/Stage/AI-Agent/venv/lib/python3.12/site-packages/celery/worker/loops.py", line 86, in asynloop
    state.maybe_shutdown()
  File "/Users/stagiaire_vycode/Stage/AI-Agent/venv/lib/python3.12/site-packages/celery/worker/state.py", line 93, in maybe_shutdown
    raise WorkerShutdown(should_stop)
celery.exceptions.WorkerShutdown: 0

During handling of the above exception, another exception occurred:

Traceback (most recent call last):
  File "/Users/stagiaire_vycode/Stage/AI-Agent/venv/lib/python3.12/site-packages/billiard/pool.py", line 1265, in mark_as_worker_lost
    raise WorkerLostError(
billiard.exceptions.WorkerLostError: Worker exited prematurely: signal 15 (SIGTERM) Job: 1.
"""
[2025-09-25 13:02:28] ERROR    [celery.worker.request:643] [MainProcess] Task handler raised error: WorkerLostError('Worker exited prematurely: signal 15 (SIGTERM) Job: 1.')
Traceback (most recent call last):
  File "/Users/stagiaire_vycode/Stage/AI-Agent/venv/lib/python3.12/site-packages/billiard/pool.py", line 1265, in mark_as_worker_lost
    raise WorkerLostError(
billiard.einfo.ExceptionWithTraceback: 
"""
Traceback (most recent call last):
  File "/Users/stagiaire_vycode/Stage/AI-Agent/venv/lib/python3.12/site-packages/celery/worker/worker.py", line 202, in start
    self.blueprint.start(self)
  File "/Users/stagiaire_vycode/Stage/AI-Agent/venv/lib/python3.12/site-packages/celery/bootsteps.py", line 116, in start
    step.start(parent)
  File "/Users/stagiaire_vycode/Stage/AI-Agent/venv/lib/python3.12/site-packages/celery/bootsteps.py", line 365, in start
    return self.obj.start()
           ^^^^^^^^^^^^^^^^
  File "/Users/stagiaire_vycode/Stage/AI-Agent/venv/lib/python3.12/site-packages/celery/worker/consumer/consumer.py", line 340, in start
    blueprint.start(self)
  File "/Users/stagiaire_vycode/Stage/AI-Agent/venv/lib/python3.12/site-packages/celery/bootsteps.py", line 116, in start
    step.start(parent)
  File "/Users/stagiaire_vycode/Stage/AI-Agent/venv/lib/python3.12/site-packages/celery/worker/consumer/consumer.py", line 742, in start
    c.loop(*c.loop_args())
  File "/Users/stagiaire_vycode/Stage/AI-Agent/venv/lib/python3.12/site-packages/celery/worker/loops.py", line 86, in asynloop
    state.maybe_shutdown()
  File "/Users/stagiaire_vycode/Stage/AI-Agent/venv/lib/python3.12/site-packages/celery/worker/state.py", line 93, in maybe_shutdown
    raise WorkerShutdown(should_stop)
celery.exceptions.WorkerShutdown: 0

During handling of the above exception, another exception occurred:

Traceback (most recent call last):
  File "/Users/stagiaire_vycode/Stage/AI-Agent/venv/lib/python3.12/site-packages/billiard/pool.py", line 1265, in mark_as_worker_lost
    raise WorkerLostError(
billiard.exceptions.WorkerLostError: Worker exited prematurely: signal 15 (SIGTERM) Job: 1.
"""
[2025-09-25 14:07:59] ERROR    [celery.worker.request:643] [MainProcess] Task handler raised error: WorkerLostError('Worker exited prematurely: signal 15 (SIGTERM) Job: 1.')
Traceback (most recent call last):
  File "/Users/stagiaire_vycode/Stage/AI-Agent/venv/lib/python3.12/site-packages/billiard/pool.py", line 1265, in mark_as_worker_lost
    raise WorkerLostError(
billiard.einfo.ExceptionWithTraceback: 
"""
Traceback (most recent call last):
  File "/Users/stagiaire_vycode/Stage/AI-Agent/venv/lib/python3.12/site-packages/celery/worker/worker.py", line 202, in start
    self.blueprint.start(self)
  File "/Users/stagiaire_vycode/Stage/AI-Agent/venv/lib/python3.12/site-packages/celery/bootsteps.py", line 116, in start
    step.start(parent)
  File "/Users/stagiaire_vycode/Stage/AI-Agent/venv/lib/python3.12/site-packages/celery/bootsteps.py", line 365, in start
    return self.obj.start()
           ^^^^^^^^^^^^^^^^
  File "/Users/stagiaire_vycode/Stage/AI-Agent/venv/lib/python3.12/site-packages/celery/worker/consumer/consumer.py", line 340, in start
    blueprint.start(self)
  File "/Users/stagiaire_vycode/Stage/AI-Agent/venv/lib/python3.12/site-packages/celery/bootsteps.py", line 116, in start
    step.start(parent)
  File "/Users/stagiaire_vycode/Stage/AI-Agent/venv/lib/python3.12/site-packages/celery/worker/consumer/consumer.py", line 742, in start
    c.loop(*c.loop_args())
  File "/Users/stagiaire_vycode/Stage/AI-Agent/venv/lib/python3.12/site-packages/celery/worker/loops.py", line 86, in asynloop
    state.maybe_shutdown()
  File "/Users/stagiaire_vycode/Stage/AI-Agent/venv/lib/python3.12/site-packages/celery/worker/state.py", line 93, in maybe_shutdown
    raise WorkerShutdown(should_stop)
celery.exceptions.WorkerShutdown: 0

During handling of the above exception, another exception occurred:

Traceback (most recent call last):
  File "/Users/stagiaire_vycode/Stage/AI-Agent/venv/lib/python3.12/site-packages/billiard/pool.py", line 1265, in mark_as_worker_lost
    raise WorkerLostError(
billiard.exceptions.WorkerLostError: Worker exited prematurely: signal 15 (SIGTERM) Job: 1.
"""
[2025-09-25 14:20:52] ERROR    [celery.worker.request:643] [MainProcess] Task handler raised error: WorkerLostError('Worker exited prematurely: signal 15 (SIGTERM) Job: 0.')
Traceback (most recent call last):
  File "/Users/stagiaire_vycode/Stage/AI-Agent/venv/lib/python3.12/site-packages/billiard/pool.py", line 1265, in mark_as_worker_lost
    raise WorkerLostError(
billiard.einfo.ExceptionWithTraceback: 
"""
Traceback (most recent call last):
  File "/Users/stagiaire_vycode/Stage/AI-Agent/venv/lib/python3.12/site-packages/celery/worker/worker.py", line 202, in start
    self.blueprint.start(self)
  File "/Users/stagiaire_vycode/Stage/AI-Agent/venv/lib/python3.12/site-packages/celery/bootsteps.py", line 116, in start
    step.start(parent)
  File "/Users/stagiaire_vycode/Stage/AI-Agent/venv/lib/python3.12/site-packages/celery/bootsteps.py", line 365, in start
    return self.obj.start()
           ^^^^^^^^^^^^^^^^
  File "/Users/stagiaire_vycode/Stage/AI-Agent/venv/lib/python3.12/site-packages/celery/worker/consumer/consumer.py", line 340, in start
    blueprint.start(self)
  File "/Users/stagiaire_vycode/Stage/AI-Agent/venv/lib/python3.12/site-packages/celery/bootsteps.py", line 116, in start
    step.start(parent)
  File "/Users/stagiaire_vycode/Stage/AI-Agent/venv/lib/python3.12/site-packages/celery/worker/consumer/consumer.py", line 742, in start
    c.loop(*c.loop_args())
  File "/Users/stagiaire_vycode/Stage/AI-Agent/venv/lib/python3.12/site-packages/celery/worker/loops.py", line 86, in asynloop
    state.maybe_shutdown()
  File "/Users/stagiaire_vycode/Stage/AI-Agent/venv/lib/python3.12/site-packages/celery/worker/state.py", line 93, in maybe_shutdown
    raise WorkerShutdown(should_stop)
celery.exceptions.WorkerShutdown: 0

During handling of the above exception, another exception occurred:

Traceback (most recent call last):
  File "/Users/stagiaire_vycode/Stage/AI-Agent/venv/lib/python3.12/site-packages/billiard/pool.py", line 1265, in mark_as_worker_lost
    raise WorkerLostError(
billiard.exceptions.WorkerLostError: Worker exited prematurely: signal 15 (SIGTERM) Job: 0.
"""
[2025-09-25 14:28:16] ERROR    [celery.worker.request:643] [MainProcess] Task handler raised error: WorkerLostError('Worker exited prematurely: signal 15 (SIGTERM) Job: 1.')
Traceback (most recent call last):
  File "/Users/stagiaire_vycode/Stage/AI-Agent/venv/lib/python3.12/site-packages/billiard/pool.py", line 1265, in mark_as_worker_lost
    raise WorkerLostError(
billiard.einfo.ExceptionWithTraceback: 
"""
Traceback (most recent call last):
  File "/Users/stagiaire_vycode/Stage/AI-Agent/venv/lib/python3.12/site-packages/celery/worker/worker.py", line 202, in start
    self.blueprint.start(self)
  File "/Users/stagiaire_vycode/Stage/AI-Agent/venv/lib/python3.12/site-packages/celery/bootsteps.py", line 116, in start
    step.start(parent)
  File "/Users/stagiaire_vycode/Stage/AI-Agent/venv/lib/python3.12/site-packages/celery/bootsteps.py", line 365, in start
    return self.obj.start()
           ^^^^^^^^^^^^^^^^
  File "/Users/stagiaire_vycode/Stage/AI-Agent/venv/lib/python3.12/site-packages/celery/worker/consumer/consumer.py", line 340, in start
    blueprint.start(self)
  File "/Users/stagiaire_vycode/Stage/AI-Agent/venv/lib/python3.12/site-packages/celery/bootsteps.py", line 116, in start
    step.start(parent)
  File "/Users/stagiaire_vycode/Stage/AI-Agent/venv/lib/python3.12/site-packages/celery/worker/consumer/consumer.py", line 742, in start
    c.loop(*c.loop_args())
  File "/Users/stagiaire_vycode/Stage/AI-Agent/venv/lib/python3.12/site-packages/celery/worker/loops.py", line 86, in asynloop
    state.maybe_shutdown()
  File "/Users/stagiaire_vycode/Stage/AI-Agent/venv/lib/python3.12/site-packages/celery/worker/state.py", line 93, in maybe_shutdown
    raise WorkerShutdown(should_stop)
celery.exceptions.WorkerShutdown: 0

During handling of the above exception, another exception occurred:

Traceback (most recent call last):
  File "/Users/stagiaire_vycode/Stage/AI-Agent/venv/lib/python3.12/site-packages/billiard/pool.py", line 1265, in mark_as_worker_lost
    raise WorkerLostError(
billiard.exceptions.WorkerLostError: Worker exited prematurely: signal 15 (SIGTERM) Job: 1.
"""
[2025-09-25 15:31:37] ERROR    [celery.worker.request:643] [MainProcess] Task handler raised error: WorkerLostError('Worker exited prematurely: signal 15 (SIGTERM) Job: 1.')
Traceback (most recent call last):
  File "/Users/stagiaire_vycode/Stage/AI-Agent/venv/lib/python3.12/site-packages/billiard/pool.py", line 1265, in mark_as_worker_lost
    raise WorkerLostError(
billiard.einfo.ExceptionWithTraceback: 
"""
Traceback (most recent call last):
  File "/Users/stagiaire_vycode/Stage/AI-Agent/venv/lib/python3.12/site-packages/celery/worker/worker.py", line 202, in start
    self.blueprint.start(self)
  File "/Users/stagiaire_vycode/Stage/AI-Agent/venv/lib/python3.12/site-packages/celery/bootsteps.py", line 116, in start
    step.start(parent)
  File "/Users/stagiaire_vycode/Stage/AI-Agent/venv/lib/python3.12/site-packages/celery/bootsteps.py", line 365, in start
    return self.obj.start()
           ^^^^^^^^^^^^^^^^
  File "/Users/stagiaire_vycode/Stage/AI-Agent/venv/lib/python3.12/site-packages/celery/worker/consumer/consumer.py", line 340, in start
    blueprint.start(self)
  File "/Users/stagiaire_vycode/Stage/AI-Agent/venv/lib/python3.12/site-packages/celery/bootsteps.py", line 116, in start
    step.start(parent)
  File "/Users/stagiaire_vycode/Stage/AI-Agent/venv/lib/python3.12/site-packages/celery/worker/consumer/consumer.py", line 742, in start
    c.loop(*c.loop_args())
  File "/Users/stagiaire_vycode/Stage/AI-Agent/venv/lib/python3.12/site-packages/celery/worker/loops.py", line 86, in asynloop
    state.maybe_shutdown()
  File "/Users/stagiaire_vycode/Stage/AI-Agent/venv/lib/python3.12/site-packages/celery/worker/state.py", line 93, in maybe_shutdown
    raise WorkerShutdown(should_stop)
celery.exceptions.WorkerShutdown: 0

During handling of the above exception, another exception occurred:

Traceback (most recent call last):
  File "/Users/stagiaire_vycode/Stage/AI-Agent/venv/lib/python3.12/site-packages/billiard/pool.py", line 1265, in mark_as_worker_lost
    raise WorkerLostError(
billiard.exceptions.WorkerLostError: Worker exited prematurely: signal 15 (SIGTERM) Job: 1.
"""
[2025-09-25 15:54:50] ERROR    [celery.worker.request:643] [MainProcess] Task handler raised error: WorkerLostError('Worker exited prematurely: signal 15 (SIGTERM) Job: 1.')
Traceback (most recent call last):
  File "/Users/stagiaire_vycode/Stage/AI-Agent/venv/lib/python3.12/site-packages/billiard/pool.py", line 1265, in mark_as_worker_lost
    raise WorkerLostError(
billiard.einfo.ExceptionWithTraceback: 
"""
Traceback (most recent call last):
  File "/Users/stagiaire_vycode/Stage/AI-Agent/venv/lib/python3.12/site-packages/celery/worker/worker.py", line 202, in start
    self.blueprint.start(self)
  File "/Users/stagiaire_vycode/Stage/AI-Agent/venv/lib/python3.12/site-packages/celery/bootsteps.py", line 116, in start
    step.start(parent)
  File "/Users/stagiaire_vycode/Stage/AI-Agent/venv/lib/python3.12/site-packages/celery/bootsteps.py", line 365, in start
    return self.obj.start()
           ^^^^^^^^^^^^^^^^
  File "/Users/stagiaire_vycode/Stage/AI-Agent/venv/lib/python3.12/site-packages/celery/worker/consumer/consumer.py", line 340, in start
    blueprint.start(self)
  File "/Users/stagiaire_vycode/Stage/AI-Agent/venv/lib/python3.12/site-packages/celery/bootsteps.py", line 116, in start
    step.start(parent)
  File "/Users/stagiaire_vycode/Stage/AI-Agent/venv/lib/python3.12/site-packages/celery/worker/consumer/consumer.py", line 742, in start
    c.loop(*c.loop_args())
  File "/Users/stagiaire_vycode/Stage/AI-Agent/venv/lib/python3.12/site-packages/celery/worker/loops.py", line 86, in asynloop
    state.maybe_shutdown()
  File "/Users/stagiaire_vycode/Stage/AI-Agent/venv/lib/python3.12/site-packages/celery/worker/state.py", line 93, in maybe_shutdown
    raise WorkerShutdown(should_stop)
celery.exceptions.WorkerShutdown: 0

During handling of the above exception, another exception occurred:

Traceback (most recent call last):
  File "/Users/stagiaire_vycode/Stage/AI-Agent/venv/lib/python3.12/site-packages/billiard/pool.py", line 1265, in mark_as_worker_lost
    raise WorkerLostError(
billiard.exceptions.WorkerLostError: Worker exited prematurely: signal 15 (SIGTERM) Job: 1.
"""
[2025-09-25 16:21:00] ERROR    [celery.worker.request:643] [MainProcess] Task handler raised error: WorkerLostError('Worker exited prematurely: signal 15 (SIGTERM) Job: 0.')
Traceback (most recent call last):
  File "/Users/stagiaire_vycode/Stage/AI-Agent/venv/lib/python3.12/site-packages/billiard/pool.py", line 1265, in mark_as_worker_lost
    raise WorkerLostError(
billiard.einfo.ExceptionWithTraceback: 
"""
Traceback (most recent call last):
  File "/Users/stagiaire_vycode/Stage/AI-Agent/venv/lib/python3.12/site-packages/celery/worker/worker.py", line 202, in start
    self.blueprint.start(self)
  File "/Users/stagiaire_vycode/Stage/AI-Agent/venv/lib/python3.12/site-packages/celery/bootsteps.py", line 116, in start
    step.start(parent)
  File "/Users/stagiaire_vycode/Stage/AI-Agent/venv/lib/python3.12/site-packages/celery/bootsteps.py", line 365, in start
    return self.obj.start()
           ^^^^^^^^^^^^^^^^
  File "/Users/stagiaire_vycode/Stage/AI-Agent/venv/lib/python3.12/site-packages/celery/worker/consumer/consumer.py", line 340, in start
    blueprint.start(self)
  File "/Users/stagiaire_vycode/Stage/AI-Agent/venv/lib/python3.12/site-packages/celery/bootsteps.py", line 116, in start
    step.start(parent)
  File "/Users/stagiaire_vycode/Stage/AI-Agent/venv/lib/python3.12/site-packages/celery/worker/consumer/consumer.py", line 742, in start
    c.loop(*c.loop_args())
  File "/Users/stagiaire_vycode/Stage/AI-Agent/venv/lib/python3.12/site-packages/celery/worker/loops.py", line 86, in asynloop
    state.maybe_shutdown()
  File "/Users/stagiaire_vycode/Stage/AI-Agent/venv/lib/python3.12/site-packages/celery/worker/state.py", line 93, in maybe_shutdown
    raise WorkerShutdown(should_stop)
celery.exceptions.WorkerShutdown: 0

During handling of the above exception, another exception occurred:

Traceback (most recent call last):
  File "/Users/stagiaire_vycode/Stage/AI-Agent/venv/lib/python3.12/site-packages/billiard/pool.py", line 1265, in mark_as_worker_lost
    raise WorkerLostError(
billiard.exceptions.WorkerLostError: Worker exited prematurely: signal 15 (SIGTERM) Job: 0.
"""
[2025-10-02 12:18:19] ERROR    [celery.worker.request:643] [MainProcess] Task handler raised error: WorkerLostError('Worker exited prematurely: signal 15 (SIGTERM) Job: 1.')
Traceback (most recent call last):
  File "/Library/Frameworks/Python.framework/Versions/3.12/lib/python3.12/site-packages/billiard/pool.py", line 1265, in mark_as_worker_lost
    raise WorkerLostError(
billiard.einfo.ExceptionWithTraceback: 
"""
Traceback (most recent call last):
  File "/Library/Frameworks/Python.framework/Versions/3.12/lib/python3.12/site-packages/celery/worker/worker.py", line 202, in start
    self.blueprint.start(self)
  File "/Library/Frameworks/Python.framework/Versions/3.12/lib/python3.12/site-packages/celery/bootsteps.py", line 116, in start
    step.start(parent)
  File "/Library/Frameworks/Python.framework/Versions/3.12/lib/python3.12/site-packages/celery/bootsteps.py", line 365, in start
    return self.obj.start()
           ^^^^^^^^^^^^^^^^
  File "/Library/Frameworks/Python.framework/Versions/3.12/lib/python3.12/site-packages/celery/worker/consumer/consumer.py", line 340, in start
    blueprint.start(self)
  File "/Library/Frameworks/Python.framework/Versions/3.12/lib/python3.12/site-packages/celery/bootsteps.py", line 116, in start
    step.start(parent)
  File "/Library/Frameworks/Python.framework/Versions/3.12/lib/python3.12/site-packages/celery/worker/consumer/consumer.py", line 742, in start
    c.loop(*c.loop_args())
  File "/Library/Frameworks/Python.framework/Versions/3.12/lib/python3.12/site-packages/celery/worker/loops.py", line 86, in asynloop
    state.maybe_shutdown()
  File "/Library/Frameworks/Python.framework/Versions/3.12/lib/python3.12/site-packages/celery/worker/state.py", line 93, in maybe_shutdown
    raise WorkerShutdown(should_stop)
celery.exceptions.WorkerShutdown: 0

During handling of the above exception, another exception occurred:

Traceback (most recent call last):
  File "/Library/Frameworks/Python.framework/Versions/3.12/lib/python3.12/site-packages/billiard/pool.py", line 1265, in mark_as_worker_lost
    raise WorkerLostError(
billiard.exceptions.WorkerLostError: Worker exited prematurely: signal 15 (SIGTERM) Job: 1.
"""
[2025-10-02 12:44:00] ERROR    [celery.worker.request:643] [MainProcess] Task handler raised error: WorkerLostError('Worker exited prematurely: signal 15 (SIGTERM) Job: 1.')
Traceback (most recent call last):
  File "/Library/Frameworks/Python.framework/Versions/3.12/lib/python3.12/site-packages/billiard/pool.py", line 1265, in mark_as_worker_lost
    raise WorkerLostError(
billiard.einfo.ExceptionWithTraceback: 
"""
Traceback (most recent call last):
  File "/Library/Frameworks/Python.framework/Versions/3.12/lib/python3.12/site-packages/celery/worker/worker.py", line 202, in start
    self.blueprint.start(self)
  File "/Library/Frameworks/Python.framework/Versions/3.12/lib/python3.12/site-packages/celery/bootsteps.py", line 116, in start
    step.start(parent)
  File "/Library/Frameworks/Python.framework/Versions/3.12/lib/python3.12/site-packages/celery/bootsteps.py", line 365, in start
    return self.obj.start()
           ^^^^^^^^^^^^^^^^
  File "/Library/Frameworks/Python.framework/Versions/3.12/lib/python3.12/site-packages/celery/worker/consumer/consumer.py", line 340, in start
    blueprint.start(self)
  File "/Library/Frameworks/Python.framework/Versions/3.12/lib/python3.12/site-packages/celery/bootsteps.py", line 116, in start
    step.start(parent)
  File "/Library/Frameworks/Python.framework/Versions/3.12/lib/python3.12/site-packages/celery/worker/consumer/consumer.py", line 742, in start
    c.loop(*c.loop_args())
  File "/Library/Frameworks/Python.framework/Versions/3.12/lib/python3.12/site-packages/celery/worker/loops.py", line 86, in asynloop
    state.maybe_shutdown()
  File "/Library/Frameworks/Python.framework/Versions/3.12/lib/python3.12/site-packages/celery/worker/state.py", line 93, in maybe_shutdown
    raise WorkerShutdown(should_stop)
celery.exceptions.WorkerShutdown: 0

During handling of the above exception, another exception occurred:

Traceback (most recent call last):
  File "/Library/Frameworks/Python.framework/Versions/3.12/lib/python3.12/site-packages/billiard/pool.py", line 1265, in mark_as_worker_lost
    raise WorkerLostError(
billiard.exceptions.WorkerLostError: Worker exited prematurely: signal 15 (SIGTERM) Job: 1.
"""
[2025-10-02 13:01:10] ERROR    [celery.worker.request:643] [MainProcess] Task handler raised error: WorkerLostError('Worker exited prematurely: signal 15 (SIGTERM) Job: 1.')
Traceback (most recent call last):
  File "/Library/Frameworks/Python.framework/Versions/3.12/lib/python3.12/site-packages/billiard/pool.py", line 1265, in mark_as_worker_lost
    raise WorkerLostError(
billiard.einfo.ExceptionWithTraceback: 
"""
Traceback (most recent call last):
  File "/Library/Frameworks/Python.framework/Versions/3.12/lib/python3.12/site-packages/celery/worker/worker.py", line 202, in start
    self.blueprint.start(self)
  File "/Library/Frameworks/Python.framework/Versions/3.12/lib/python3.12/site-packages/celery/bootsteps.py", line 116, in start
    step.start(parent)
  File "/Library/Frameworks/Python.framework/Versions/3.12/lib/python3.12/site-packages/celery/bootsteps.py", line 365, in start
    return self.obj.start()
           ^^^^^^^^^^^^^^^^
  File "/Library/Frameworks/Python.framework/Versions/3.12/lib/python3.12/site-packages/celery/worker/consumer/consumer.py", line 340, in start
    blueprint.start(self)
  File "/Library/Frameworks/Python.framework/Versions/3.12/lib/python3.12/site-packages/celery/bootsteps.py", line 116, in start
    step.start(parent)
  File "/Library/Frameworks/Python.framework/Versions/3.12/lib/python3.12/site-packages/celery/worker/consumer/consumer.py", line 742, in start
    c.loop(*c.loop_args())
  File "/Library/Frameworks/Python.framework/Versions/3.12/lib/python3.12/site-packages/celery/worker/loops.py", line 86, in asynloop
    state.maybe_shutdown()
  File "/Library/Frameworks/Python.framework/Versions/3.12/lib/python3.12/site-packages/celery/worker/state.py", line 93, in maybe_shutdown
    raise WorkerShutdown(should_stop)
celery.exceptions.WorkerShutdown: 0

During handling of the above exception, another exception occurred:

Traceback (most recent call last):
  File "/Library/Frameworks/Python.framework/Versions/3.12/lib/python3.12/site-packages/billiard/pool.py", line 1265, in mark_as_worker_lost
    raise WorkerLostError(
billiard.exceptions.WorkerLostError: Worker exited prematurely: signal 15 (SIGTERM) Job: 1.
"""
[2025-10-02 16:04:44] ERROR    [celery.worker.request:643] [MainProcess] Task handler raised error: WorkerLostError('Worker exited prematurely: signal 15 (SIGTERM) Job: 0.')
Traceback (most recent call last):
  File "/Library/Frameworks/Python.framework/Versions/3.12/lib/python3.12/site-packages/billiard/pool.py", line 1265, in mark_as_worker_lost
    raise WorkerLostError(
billiard.einfo.ExceptionWithTraceback: 
"""
Traceback (most recent call last):
  File "/Library/Frameworks/Python.framework/Versions/3.12/lib/python3.12/site-packages/celery/worker/worker.py", line 202, in start
    self.blueprint.start(self)
  File "/Library/Frameworks/Python.framework/Versions/3.12/lib/python3.12/site-packages/celery/bootsteps.py", line 116, in start
    step.start(parent)
  File "/Library/Frameworks/Python.framework/Versions/3.12/lib/python3.12/site-packages/celery/bootsteps.py", line 365, in start
    return self.obj.start()
           ^^^^^^^^^^^^^^^^
  File "/Library/Frameworks/Python.framework/Versions/3.12/lib/python3.12/site-packages/celery/worker/consumer/consumer.py", line 340, in start
    blueprint.start(self)
  File "/Library/Frameworks/Python.framework/Versions/3.12/lib/python3.12/site-packages/celery/bootsteps.py", line 116, in start
    step.start(parent)
  File "/Library/Frameworks/Python.framework/Versions/3.12/lib/python3.12/site-packages/celery/worker/consumer/consumer.py", line 742, in start
    c.loop(*c.loop_args())
  File "/Library/Frameworks/Python.framework/Versions/3.12/lib/python3.12/site-packages/celery/worker/loops.py", line 86, in asynloop
    state.maybe_shutdown()
  File "/Library/Frameworks/Python.framework/Versions/3.12/lib/python3.12/site-packages/celery/worker/state.py", line 93, in maybe_shutdown
    raise WorkerShutdown(should_stop)
celery.exceptions.WorkerShutdown: 0

During handling of the above exception, another exception occurred:

Traceback (most recent call last):
  File "/Library/Frameworks/Python.framework/Versions/3.12/lib/python3.12/site-packages/billiard/pool.py", line 1265, in mark_as_worker_lost
    raise WorkerLostError(
billiard.exceptions.WorkerLostError: Worker exited prematurely: signal 15 (SIGTERM) Job: 0.
"""
[2025-10-02 16:06:59] ERROR    [celery.worker.request:643] [MainProcess] Task handler raised error: WorkerLostError('Worker exited prematurely: signal 15 (SIGTERM) Job: 1.')
Traceback (most recent call last):
  File "/Library/Frameworks/Python.framework/Versions/3.12/lib/python3.12/site-packages/billiard/pool.py", line 1265, in mark_as_worker_lost
    raise WorkerLostError(
billiard.einfo.ExceptionWithTraceback: 
"""
Traceback (most recent call last):
  File "/Library/Frameworks/Python.framework/Versions/3.12/lib/python3.12/site-packages/celery/worker/worker.py", line 202, in start
    self.blueprint.start(self)
  File "/Library/Frameworks/Python.framework/Versions/3.12/lib/python3.12/site-packages/celery/bootsteps.py", line 116, in start
    step.start(parent)
  File "/Library/Frameworks/Python.framework/Versions/3.12/lib/python3.12/site-packages/celery/bootsteps.py", line 365, in start
    return self.obj.start()
           ^^^^^^^^^^^^^^^^
  File "/Library/Frameworks/Python.framework/Versions/3.12/lib/python3.12/site-packages/celery/worker/consumer/consumer.py", line 340, in start
    blueprint.start(self)
  File "/Library/Frameworks/Python.framework/Versions/3.12/lib/python3.12/site-packages/celery/bootsteps.py", line 116, in start
    step.start(parent)
  File "/Library/Frameworks/Python.framework/Versions/3.12/lib/python3.12/site-packages/celery/worker/consumer/consumer.py", line 742, in start
    c.loop(*c.loop_args())
  File "/Library/Frameworks/Python.framework/Versions/3.12/lib/python3.12/site-packages/celery/worker/loops.py", line 86, in asynloop
    state.maybe_shutdown()
  File "/Library/Frameworks/Python.framework/Versions/3.12/lib/python3.12/site-packages/celery/worker/state.py", line 93, in maybe_shutdown
    raise WorkerShutdown(should_stop)
celery.exceptions.WorkerShutdown: 0

During handling of the above exception, another exception occurred:

Traceback (most recent call last):
  File "/Library/Frameworks/Python.framework/Versions/3.12/lib/python3.12/site-packages/billiard/pool.py", line 1265, in mark_as_worker_lost
    raise WorkerLostError(
billiard.exceptions.WorkerLostError: Worker exited prematurely: signal 15 (SIGTERM) Job: 1.
"""
[2025-10-02 16:32:36] ERROR    [celery.worker.request:643] [MainProcess] Task handler raised error: WorkerLostError('Worker exited prematurely: signal 15 (SIGTERM) Job: 1.')
Traceback (most recent call last):
  File "/Library/Frameworks/Python.framework/Versions/3.12/lib/python3.12/site-packages/billiard/pool.py", line 1265, in mark_as_worker_lost
    raise WorkerLostError(
billiard.einfo.ExceptionWithTraceback: 
"""
Traceback (most recent call last):
  File "/Library/Frameworks/Python.framework/Versions/3.12/lib/python3.12/site-packages/celery/worker/worker.py", line 202, in start
    self.blueprint.start(self)
  File "/Library/Frameworks/Python.framework/Versions/3.12/lib/python3.12/site-packages/celery/bootsteps.py", line 116, in start
    step.start(parent)
  File "/Library/Frameworks/Python.framework/Versions/3.12/lib/python3.12/site-packages/celery/bootsteps.py", line 365, in start
    return self.obj.start()
           ^^^^^^^^^^^^^^^^
  File "/Library/Frameworks/Python.framework/Versions/3.12/lib/python3.12/site-packages/celery/worker/consumer/consumer.py", line 340, in start
    blueprint.start(self)
  File "/Library/Frameworks/Python.framework/Versions/3.12/lib/python3.12/site-packages/celery/bootsteps.py", line 116, in start
    step.start(parent)
  File "/Library/Frameworks/Python.framework/Versions/3.12/lib/python3.12/site-packages/celery/worker/consumer/consumer.py", line 742, in start
    c.loop(*c.loop_args())
  File "/Library/Frameworks/Python.framework/Versions/3.12/lib/python3.12/site-packages/celery/worker/loops.py", line 86, in asynloop
    state.maybe_shutdown()
  File "/Library/Frameworks/Python.framework/Versions/3.12/lib/python3.12/site-packages/celery/worker/state.py", line 93, in maybe_shutdown
    raise WorkerShutdown(should_stop)
celery.exceptions.WorkerShutdown: 0

During handling of the above exception, another exception occurred:

Traceback (most recent call last):
  File "/Library/Frameworks/Python.framework/Versions/3.12/lib/python3.12/site-packages/billiard/pool.py", line 1265, in mark_as_worker_lost
    raise WorkerLostError(
billiard.exceptions.WorkerLostError: Worker exited prematurely: signal 15 (SIGTERM) Job: 1.
"""
[2025-10-02 17:08:34] ERROR    [celery.worker.request:643] [MainProcess] Task handler raised error: WorkerLostError('Worker exited prematurely: signal 15 (SIGTERM) Job: 1.')
Traceback (most recent call last):
  File "/Library/Frameworks/Python.framework/Versions/3.12/lib/python3.12/site-packages/billiard/pool.py", line 1265, in mark_as_worker_lost
    raise WorkerLostError(
billiard.einfo.ExceptionWithTraceback: 
"""
Traceback (most recent call last):
  File "/Library/Frameworks/Python.framework/Versions/3.12/lib/python3.12/site-packages/celery/worker/worker.py", line 202, in start
    self.blueprint.start(self)
  File "/Library/Frameworks/Python.framework/Versions/3.12/lib/python3.12/site-packages/celery/bootsteps.py", line 116, in start
    step.start(parent)
  File "/Library/Frameworks/Python.framework/Versions/3.12/lib/python3.12/site-packages/celery/bootsteps.py", line 365, in start
    return self.obj.start()
           ^^^^^^^^^^^^^^^^
  File "/Library/Frameworks/Python.framework/Versions/3.12/lib/python3.12/site-packages/celery/worker/consumer/consumer.py", line 340, in start
    blueprint.start(self)
  File "/Library/Frameworks/Python.framework/Versions/3.12/lib/python3.12/site-packages/celery/bootsteps.py", line 116, in start
    step.start(parent)
  File "/Library/Frameworks/Python.framework/Versions/3.12/lib/python3.12/site-packages/celery/worker/consumer/consumer.py", line 742, in start
    c.loop(*c.loop_args())
  File "/Library/Frameworks/Python.framework/Versions/3.12/lib/python3.12/site-packages/celery/worker/loops.py", line 86, in asynloop
    state.maybe_shutdown()
  File "/Library/Frameworks/Python.framework/Versions/3.12/lib/python3.12/site-packages/celery/worker/state.py", line 93, in maybe_shutdown
    raise WorkerShutdown(should_stop)
celery.exceptions.WorkerShutdown: 0

During handling of the above exception, another exception occurred:

Traceback (most recent call last):
  File "/Library/Frameworks/Python.framework/Versions/3.12/lib/python3.12/site-packages/billiard/pool.py", line 1265, in mark_as_worker_lost
    raise WorkerLostError(
billiard.exceptions.WorkerLostError: Worker exited prematurely: signal 15 (SIGTERM) Job: 1.
"""
[2025-10-02 17:18:27] ERROR    [celery.worker.request:643] [MainProcess] Task handler raised error: WorkerLostError('Worker exited prematurely: signal 15 (SIGTERM) Job: 1.')
Traceback (most recent call last):
  File "/Library/Frameworks/Python.framework/Versions/3.12/lib/python3.12/site-packages/billiard/pool.py", line 1265, in mark_as_worker_lost
    raise WorkerLostError(
billiard.einfo.ExceptionWithTraceback: 
"""
Traceback (most recent call last):
  File "/Library/Frameworks/Python.framework/Versions/3.12/lib/python3.12/site-packages/celery/worker/worker.py", line 202, in start
    self.blueprint.start(self)
  File "/Library/Frameworks/Python.framework/Versions/3.12/lib/python3.12/site-packages/celery/bootsteps.py", line 116, in start
    step.start(parent)
  File "/Library/Frameworks/Python.framework/Versions/3.12/lib/python3.12/site-packages/celery/bootsteps.py", line 365, in start
    return self.obj.start()
           ^^^^^^^^^^^^^^^^
  File "/Library/Frameworks/Python.framework/Versions/3.12/lib/python3.12/site-packages/celery/worker/consumer/consumer.py", line 340, in start
    blueprint.start(self)
  File "/Library/Frameworks/Python.framework/Versions/3.12/lib/python3.12/site-packages/celery/bootsteps.py", line 116, in start
    step.start(parent)
  File "/Library/Frameworks/Python.framework/Versions/3.12/lib/python3.12/site-packages/celery/worker/consumer/consumer.py", line 742, in start
    c.loop(*c.loop_args())
  File "/Library/Frameworks/Python.framework/Versions/3.12/lib/python3.12/site-packages/celery/worker/loops.py", line 86, in asynloop
    state.maybe_shutdown()
  File "/Library/Frameworks/Python.framework/Versions/3.12/lib/python3.12/site-packages/celery/worker/state.py", line 93, in maybe_shutdown
    raise WorkerShutdown(should_stop)
celery.exceptions.WorkerShutdown: 0

During handling of the above exception, another exception occurred:

Traceback (most recent call last):
  File "/Library/Frameworks/Python.framework/Versions/3.12/lib/python3.12/site-packages/billiard/pool.py", line 1265, in mark_as_worker_lost
    raise WorkerLostError(
billiard.exceptions.WorkerLostError: Worker exited prematurely: signal 15 (SIGTERM) Job: 1.
"""
[2025-10-02 17:33:05] ERROR    [celery.worker.request:643] [MainProcess] Task handler raised error: WorkerLostError('Worker exited prematurely: signal 15 (SIGTERM) Job: 1.')
Traceback (most recent call last):
  File "/Library/Frameworks/Python.framework/Versions/3.12/lib/python3.12/site-packages/billiard/pool.py", line 1265, in mark_as_worker_lost
    raise WorkerLostError(
billiard.einfo.ExceptionWithTraceback: 
"""
Traceback (most recent call last):
  File "/Library/Frameworks/Python.framework/Versions/3.12/lib/python3.12/site-packages/celery/worker/worker.py", line 202, in start
    self.blueprint.start(self)
  File "/Library/Frameworks/Python.framework/Versions/3.12/lib/python3.12/site-packages/celery/bootsteps.py", line 116, in start
    step.start(parent)
  File "/Library/Frameworks/Python.framework/Versions/3.12/lib/python3.12/site-packages/celery/bootsteps.py", line 365, in start
    return self.obj.start()
           ^^^^^^^^^^^^^^^^
  File "/Library/Frameworks/Python.framework/Versions/3.12/lib/python3.12/site-packages/celery/worker/consumer/consumer.py", line 340, in start
    blueprint.start(self)
  File "/Library/Frameworks/Python.framework/Versions/3.12/lib/python3.12/site-packages/celery/bootsteps.py", line 116, in start
    step.start(parent)
  File "/Library/Frameworks/Python.framework/Versions/3.12/lib/python3.12/site-packages/celery/worker/consumer/consumer.py", line 742, in start
    c.loop(*c.loop_args())
  File "/Library/Frameworks/Python.framework/Versions/3.12/lib/python3.12/site-packages/celery/worker/loops.py", line 86, in asynloop
    state.maybe_shutdown()
  File "/Library/Frameworks/Python.framework/Versions/3.12/lib/python3.12/site-packages/celery/worker/state.py", line 93, in maybe_shutdown
    raise WorkerShutdown(should_stop)
celery.exceptions.WorkerShutdown: 0

During handling of the above exception, another exception occurred:

Traceback (most recent call last):
  File "/Library/Frameworks/Python.framework/Versions/3.12/lib/python3.12/site-packages/billiard/pool.py", line 1265, in mark_as_worker_lost
    raise WorkerLostError(
billiard.exceptions.WorkerLostError: Worker exited prematurely: signal 15 (SIGTERM) Job: 1.
"""
[2025-10-02 17:58:22] ERROR    [celery.worker.request:643] [MainProcess] Task handler raised error: WorkerLostError('Worker exited prematurely: signal 15 (SIGTERM) Job: 1.')
Traceback (most recent call last):
  File "/Library/Frameworks/Python.framework/Versions/3.12/lib/python3.12/site-packages/billiard/pool.py", line 1265, in mark_as_worker_lost
    raise WorkerLostError(
billiard.einfo.ExceptionWithTraceback: 
"""
Traceback (most recent call last):
  File "/Library/Frameworks/Python.framework/Versions/3.12/lib/python3.12/site-packages/celery/worker/worker.py", line 202, in start
    self.blueprint.start(self)
  File "/Library/Frameworks/Python.framework/Versions/3.12/lib/python3.12/site-packages/celery/bootsteps.py", line 116, in start
    step.start(parent)
  File "/Library/Frameworks/Python.framework/Versions/3.12/lib/python3.12/site-packages/celery/bootsteps.py", line 365, in start
    return self.obj.start()
           ^^^^^^^^^^^^^^^^
  File "/Library/Frameworks/Python.framework/Versions/3.12/lib/python3.12/site-packages/celery/worker/consumer/consumer.py", line 340, in start
    blueprint.start(self)
  File "/Library/Frameworks/Python.framework/Versions/3.12/lib/python3.12/site-packages/celery/bootsteps.py", line 116, in start
    step.start(parent)
  File "/Library/Frameworks/Python.framework/Versions/3.12/lib/python3.12/site-packages/celery/worker/consumer/consumer.py", line 742, in start
    c.loop(*c.loop_args())
  File "/Library/Frameworks/Python.framework/Versions/3.12/lib/python3.12/site-packages/celery/worker/loops.py", line 86, in asynloop
    state.maybe_shutdown()
  File "/Library/Frameworks/Python.framework/Versions/3.12/lib/python3.12/site-packages/celery/worker/state.py", line 93, in maybe_shutdown
    raise WorkerShutdown(should_stop)
celery.exceptions.WorkerShutdown: 0

During handling of the above exception, another exception occurred:

Traceback (most recent call last):
  File "/Library/Frameworks/Python.framework/Versions/3.12/lib/python3.12/site-packages/billiard/pool.py", line 1265, in mark_as_worker_lost
    raise WorkerLostError(
billiard.exceptions.WorkerLostError: Worker exited prematurely: signal 15 (SIGTERM) Job: 1.
"""
[2025-10-03 14:34:28] ERROR    [celery.worker.request:643] [MainProcess] Task handler raised error: WorkerLostError('Worker exited prematurely: signal 11 (SIGSEGV) Job: 1.')
Traceback (most recent call last):
  File "/Library/Frameworks/Python.framework/Versions/3.12/lib/python3.12/site-packages/billiard/pool.py", line 1265, in mark_as_worker_lost
    raise WorkerLostError(
billiard.einfo.ExceptionWithTraceback: 
"""
Traceback (most recent call last):
  File "/Library/Frameworks/Python.framework/Versions/3.12/lib/python3.12/site-packages/billiard/pool.py", line 1265, in mark_as_worker_lost
    raise WorkerLostError(
billiard.exceptions.WorkerLostError: Worker exited prematurely: signal 11 (SIGSEGV) Job: 1.
"""
[2025-10-06 12:30:07] ERROR    [celery.worker.request:643] [MainProcess] Task handler raised error: WorkerLostError('Worker exited prematurely: signal 15 (SIGTERM) Job: 1.')
Traceback (most recent call last):
  File "/Library/Frameworks/Python.framework/Versions/3.12/lib/python3.12/site-packages/billiard/pool.py", line 1265, in mark_as_worker_lost
    raise WorkerLostError(
billiard.einfo.ExceptionWithTraceback: 
"""
Traceback (most recent call last):
  File "/Library/Frameworks/Python.framework/Versions/3.12/lib/python3.12/site-packages/celery/worker/worker.py", line 202, in start
    self.blueprint.start(self)
  File "/Library/Frameworks/Python.framework/Versions/3.12/lib/python3.12/site-packages/celery/bootsteps.py", line 116, in start
    step.start(parent)
  File "/Library/Frameworks/Python.framework/Versions/3.12/lib/python3.12/site-packages/celery/bootsteps.py", line 365, in start
    return self.obj.start()
           ^^^^^^^^^^^^^^^^
  File "/Library/Frameworks/Python.framework/Versions/3.12/lib/python3.12/site-packages/celery/worker/consumer/consumer.py", line 340, in start
    blueprint.start(self)
  File "/Library/Frameworks/Python.framework/Versions/3.12/lib/python3.12/site-packages/celery/bootsteps.py", line 116, in start
    step.start(parent)
  File "/Library/Frameworks/Python.framework/Versions/3.12/lib/python3.12/site-packages/celery/worker/consumer/consumer.py", line 742, in start
    c.loop(*c.loop_args())
  File "/Library/Frameworks/Python.framework/Versions/3.12/lib/python3.12/site-packages/celery/worker/loops.py", line 86, in asynloop
    state.maybe_shutdown()
  File "/Library/Frameworks/Python.framework/Versions/3.12/lib/python3.12/site-packages/celery/worker/state.py", line 93, in maybe_shutdown
    raise WorkerShutdown(should_stop)
celery.exceptions.WorkerShutdown: 0

During handling of the above exception, another exception occurred:

Traceback (most recent call last):
  File "/Library/Frameworks/Python.framework/Versions/3.12/lib/python3.12/site-packages/billiard/pool.py", line 1265, in mark_as_worker_lost
    raise WorkerLostError(
billiard.exceptions.WorkerLostError: Worker exited prematurely: signal 15 (SIGTERM) Job: 1.
"""
[2025-10-06 12:40:31] ERROR    [celery.worker.request:643] [MainProcess] Task handler raised error: WorkerLostError('Worker exited prematurely: signal 15 (SIGTERM) Job: 1.')
Traceback (most recent call last):
  File "/Library/Frameworks/Python.framework/Versions/3.12/lib/python3.12/site-packages/billiard/pool.py", line 1265, in mark_as_worker_lost
    raise WorkerLostError(
billiard.einfo.ExceptionWithTraceback: 
"""
Traceback (most recent call last):
  File "/Library/Frameworks/Python.framework/Versions/3.12/lib/python3.12/site-packages/celery/worker/worker.py", line 202, in start
    self.blueprint.start(self)
  File "/Library/Frameworks/Python.framework/Versions/3.12/lib/python3.12/site-packages/celery/bootsteps.py", line 116, in start
    step.start(parent)
  File "/Library/Frameworks/Python.framework/Versions/3.12/lib/python3.12/site-packages/celery/bootsteps.py", line 365, in start
    return self.obj.start()
           ^^^^^^^^^^^^^^^^
  File "/Library/Frameworks/Python.framework/Versions/3.12/lib/python3.12/site-packages/celery/worker/consumer/consumer.py", line 340, in start
    blueprint.start(self)
  File "/Library/Frameworks/Python.framework/Versions/3.12/lib/python3.12/site-packages/celery/bootsteps.py", line 116, in start
    step.start(parent)
  File "/Library/Frameworks/Python.framework/Versions/3.12/lib/python3.12/site-packages/celery/worker/consumer/consumer.py", line 742, in start
    c.loop(*c.loop_args())
  File "/Library/Frameworks/Python.framework/Versions/3.12/lib/python3.12/site-packages/celery/worker/loops.py", line 86, in asynloop
    state.maybe_shutdown()
  File "/Library/Frameworks/Python.framework/Versions/3.12/lib/python3.12/site-packages/celery/worker/state.py", line 93, in maybe_shutdown
    raise WorkerShutdown(should_stop)
celery.exceptions.WorkerShutdown: 0

During handling of the above exception, another exception occurred:

Traceback (most recent call last):
  File "/Library/Frameworks/Python.framework/Versions/3.12/lib/python3.12/site-packages/billiard/pool.py", line 1265, in mark_as_worker_lost
    raise WorkerLostError(
billiard.exceptions.WorkerLostError: Worker exited prematurely: signal 15 (SIGTERM) Job: 1.
"""
[2025-10-06 14:36:51] ERROR    [celery.worker.request:643] [MainProcess] Task handler raised error: WorkerLostError('Worker exited prematurely: signal 15 (SIGTERM) Job: 1.')
Traceback (most recent call last):
  File "/Library/Frameworks/Python.framework/Versions/3.12/lib/python3.12/site-packages/billiard/pool.py", line 1265, in mark_as_worker_lost
    raise WorkerLostError(
billiard.einfo.ExceptionWithTraceback: 
"""
Traceback (most recent call last):
  File "/Library/Frameworks/Python.framework/Versions/3.12/lib/python3.12/site-packages/celery/worker/worker.py", line 202, in start
    self.blueprint.start(self)
  File "/Library/Frameworks/Python.framework/Versions/3.12/lib/python3.12/site-packages/celery/bootsteps.py", line 116, in start
    step.start(parent)
  File "/Library/Frameworks/Python.framework/Versions/3.12/lib/python3.12/site-packages/celery/bootsteps.py", line 365, in start
    return self.obj.start()
           ^^^^^^^^^^^^^^^^
  File "/Library/Frameworks/Python.framework/Versions/3.12/lib/python3.12/site-packages/celery/worker/consumer/consumer.py", line 340, in start
    blueprint.start(self)
  File "/Library/Frameworks/Python.framework/Versions/3.12/lib/python3.12/site-packages/celery/bootsteps.py", line 116, in start
    step.start(parent)
  File "/Library/Frameworks/Python.framework/Versions/3.12/lib/python3.12/site-packages/celery/worker/consumer/consumer.py", line 742, in start
    c.loop(*c.loop_args())
  File "/Library/Frameworks/Python.framework/Versions/3.12/lib/python3.12/site-packages/celery/worker/loops.py", line 86, in asynloop
    state.maybe_shutdown()
  File "/Library/Frameworks/Python.framework/Versions/3.12/lib/python3.12/site-packages/celery/worker/state.py", line 93, in maybe_shutdown
    raise WorkerShutdown(should_stop)
celery.exceptions.WorkerShutdown: 0

During handling of the above exception, another exception occurred:

Traceback (most recent call last):
  File "/Library/Frameworks/Python.framework/Versions/3.12/lib/python3.12/site-packages/billiard/pool.py", line 1265, in mark_as_worker_lost
    raise WorkerLostError(
billiard.exceptions.WorkerLostError: Worker exited prematurely: signal 15 (SIGTERM) Job: 1.
"""
[2025-10-06 15:03:55] ERROR    [celery.worker.request:643] [MainProcess] Task handler raised error: WorkerLostError('Worker exited prematurely: signal 15 (SIGTERM) Job: 1.')
Traceback (most recent call last):
  File "/Library/Frameworks/Python.framework/Versions/3.12/lib/python3.12/site-packages/billiard/pool.py", line 1265, in mark_as_worker_lost
    raise WorkerLostError(
billiard.einfo.ExceptionWithTraceback: 
"""
Traceback (most recent call last):
  File "/Library/Frameworks/Python.framework/Versions/3.12/lib/python3.12/site-packages/celery/worker/worker.py", line 202, in start
    self.blueprint.start(self)
  File "/Library/Frameworks/Python.framework/Versions/3.12/lib/python3.12/site-packages/celery/bootsteps.py", line 116, in start
    step.start(parent)
  File "/Library/Frameworks/Python.framework/Versions/3.12/lib/python3.12/site-packages/celery/bootsteps.py", line 365, in start
    return self.obj.start()
           ^^^^^^^^^^^^^^^^
  File "/Library/Frameworks/Python.framework/Versions/3.12/lib/python3.12/site-packages/celery/worker/consumer/consumer.py", line 340, in start
    blueprint.start(self)
  File "/Library/Frameworks/Python.framework/Versions/3.12/lib/python3.12/site-packages/celery/bootsteps.py", line 116, in start
    step.start(parent)
  File "/Library/Frameworks/Python.framework/Versions/3.12/lib/python3.12/site-packages/celery/worker/consumer/consumer.py", line 742, in start
    c.loop(*c.loop_args())
  File "/Library/Frameworks/Python.framework/Versions/3.12/lib/python3.12/site-packages/celery/worker/loops.py", line 86, in asynloop
    state.maybe_shutdown()
  File "/Library/Frameworks/Python.framework/Versions/3.12/lib/python3.12/site-packages/celery/worker/state.py", line 93, in maybe_shutdown
    raise WorkerShutdown(should_stop)
celery.exceptions.WorkerShutdown: 0

During handling of the above exception, another exception occurred:

Traceback (most recent call last):
  File "/Library/Frameworks/Python.framework/Versions/3.12/lib/python3.12/site-packages/billiard/pool.py", line 1265, in mark_as_worker_lost
    raise WorkerLostError(
billiard.exceptions.WorkerLostError: Worker exited prematurely: signal 15 (SIGTERM) Job: 1.
"""
[2025-10-11 16:27:50] ERROR    [celery.worker.request:643] [MainProcess] Task handler raised error: WorkerLostError('Worker exited prematurely: signal 15 (SIGTERM) Job: 1.')
Traceback (most recent call last):
  File "/Library/Frameworks/Python.framework/Versions/3.12/lib/python3.12/site-packages/billiard/pool.py", line 1265, in mark_as_worker_lost
    raise WorkerLostError(
billiard.einfo.ExceptionWithTraceback: 
"""
Traceback (most recent call last):
  File "/Library/Frameworks/Python.framework/Versions/3.12/lib/python3.12/site-packages/celery/worker/worker.py", line 202, in start
    self.blueprint.start(self)
  File "/Library/Frameworks/Python.framework/Versions/3.12/lib/python3.12/site-packages/celery/bootsteps.py", line 116, in start
    step.start(parent)
  File "/Library/Frameworks/Python.framework/Versions/3.12/lib/python3.12/site-packages/celery/bootsteps.py", line 365, in start
    return self.obj.start()
           ^^^^^^^^^^^^^^^^
  File "/Library/Frameworks/Python.framework/Versions/3.12/lib/python3.12/site-packages/celery/worker/consumer/consumer.py", line 340, in start
    blueprint.start(self)
  File "/Library/Frameworks/Python.framework/Versions/3.12/lib/python3.12/site-packages/celery/bootsteps.py", line 116, in start
    step.start(parent)
  File "/Library/Frameworks/Python.framework/Versions/3.12/lib/python3.12/site-packages/celery/worker/consumer/consumer.py", line 742, in start
    c.loop(*c.loop_args())
  File "/Library/Frameworks/Python.framework/Versions/3.12/lib/python3.12/site-packages/celery/worker/loops.py", line 86, in asynloop
    state.maybe_shutdown()
  File "/Library/Frameworks/Python.framework/Versions/3.12/lib/python3.12/site-packages/celery/worker/state.py", line 93, in maybe_shutdown
    raise WorkerShutdown(should_stop)
celery.exceptions.WorkerShutdown: 0

During handling of the above exception, another exception occurred:

Traceback (most recent call last):
  File "/Library/Frameworks/Python.framework/Versions/3.12/lib/python3.12/site-packages/billiard/pool.py", line 1265, in mark_as_worker_lost
    raise WorkerLostError(
billiard.exceptions.WorkerLostError: Worker exited prematurely: signal 15 (SIGTERM) Job: 1.
"""
[2025-10-11 21:22:20] ERROR    [celery.worker.request:643] [MainProcess] Task handler raised error: WorkerLostError('Worker exited prematurely: signal 15 (SIGTERM) Job: 1.')
Traceback (most recent call last):
  File "/Library/Frameworks/Python.framework/Versions/3.12/lib/python3.12/site-packages/billiard/pool.py", line 1265, in mark_as_worker_lost
    raise WorkerLostError(
billiard.einfo.ExceptionWithTraceback: 
"""
Traceback (most recent call last):
  File "/Library/Frameworks/Python.framework/Versions/3.12/lib/python3.12/site-packages/celery/worker/worker.py", line 202, in start
    self.blueprint.start(self)
  File "/Library/Frameworks/Python.framework/Versions/3.12/lib/python3.12/site-packages/celery/bootsteps.py", line 116, in start
    step.start(parent)
  File "/Library/Frameworks/Python.framework/Versions/3.12/lib/python3.12/site-packages/celery/bootsteps.py", line 365, in start
    return self.obj.start()
           ^^^^^^^^^^^^^^^^
  File "/Library/Frameworks/Python.framework/Versions/3.12/lib/python3.12/site-packages/celery/worker/consumer/consumer.py", line 340, in start
    blueprint.start(self)
  File "/Library/Frameworks/Python.framework/Versions/3.12/lib/python3.12/site-packages/celery/bootsteps.py", line 116, in start
    step.start(parent)
  File "/Library/Frameworks/Python.framework/Versions/3.12/lib/python3.12/site-packages/celery/worker/consumer/consumer.py", line 742, in start
    c.loop(*c.loop_args())
  File "/Library/Frameworks/Python.framework/Versions/3.12/lib/python3.12/site-packages/celery/worker/loops.py", line 86, in asynloop
    state.maybe_shutdown()
  File "/Library/Frameworks/Python.framework/Versions/3.12/lib/python3.12/site-packages/celery/worker/state.py", line 93, in maybe_shutdown
    raise WorkerShutdown(should_stop)
celery.exceptions.WorkerShutdown: 0

During handling of the above exception, another exception occurred:

Traceback (most recent call last):
  File "/Library/Frameworks/Python.framework/Versions/3.12/lib/python3.12/site-packages/billiard/pool.py", line 1265, in mark_as_worker_lost
    raise WorkerLostError(
billiard.exceptions.WorkerLostError: Worker exited prematurely: signal 15 (SIGTERM) Job: 1.
"""
[2025-10-11 22:57:18] ERROR    [celery.worker.request:643] [MainProcess] Task handler raised error: WorkerLostError('Worker exited prematurely: signal 15 (SIGTERM) Job: 1.')
Traceback (most recent call last):
  File "/Library/Frameworks/Python.framework/Versions/3.12/lib/python3.12/site-packages/billiard/pool.py", line 1265, in mark_as_worker_lost
    raise WorkerLostError(
billiard.einfo.ExceptionWithTraceback: 
"""
Traceback (most recent call last):
  File "/Library/Frameworks/Python.framework/Versions/3.12/lib/python3.12/site-packages/celery/worker/worker.py", line 202, in start
    self.blueprint.start(self)
  File "/Library/Frameworks/Python.framework/Versions/3.12/lib/python3.12/site-packages/celery/bootsteps.py", line 116, in start
    step.start(parent)
  File "/Library/Frameworks/Python.framework/Versions/3.12/lib/python3.12/site-packages/celery/bootsteps.py", line 365, in start
    return self.obj.start()
           ^^^^^^^^^^^^^^^^
  File "/Library/Frameworks/Python.framework/Versions/3.12/lib/python3.12/site-packages/celery/worker/consumer/consumer.py", line 340, in start
    blueprint.start(self)
  File "/Library/Frameworks/Python.framework/Versions/3.12/lib/python3.12/site-packages/celery/bootsteps.py", line 116, in start
    step.start(parent)
  File "/Library/Frameworks/Python.framework/Versions/3.12/lib/python3.12/site-packages/celery/worker/consumer/consumer.py", line 742, in start
    c.loop(*c.loop_args())
  File "/Library/Frameworks/Python.framework/Versions/3.12/lib/python3.12/site-packages/celery/worker/loops.py", line 86, in asynloop
    state.maybe_shutdown()
  File "/Library/Frameworks/Python.framework/Versions/3.12/lib/python3.12/site-packages/celery/worker/state.py", line 93, in maybe_shutdown
    raise WorkerShutdown(should_stop)
celery.exceptions.WorkerShutdown: 0

During handling of the above exception, another exception occurred:

Traceback (most recent call last):
  File "/Library/Frameworks/Python.framework/Versions/3.12/lib/python3.12/site-packages/billiard/pool.py", line 1265, in mark_as_worker_lost
    raise WorkerLostError(
billiard.exceptions.WorkerLostError: Worker exited prematurely: signal 15 (SIGTERM) Job: 1.
"""
[2025-10-12 11:19:57] ERROR    [celery.worker.request:643] [MainProcess] Task handler raised error: WorkerLostError('Worker exited prematurely: signal 15 (SIGTERM) Job: 1.')
Traceback (most recent call last):
  File "/Library/Frameworks/Python.framework/Versions/3.12/lib/python3.12/site-packages/billiard/pool.py", line 1265, in mark_as_worker_lost
    raise WorkerLostError(
billiard.einfo.ExceptionWithTraceback: 
"""
Traceback (most recent call last):
  File "/Library/Frameworks/Python.framework/Versions/3.12/lib/python3.12/site-packages/celery/worker/worker.py", line 202, in start
    self.blueprint.start(self)
  File "/Library/Frameworks/Python.framework/Versions/3.12/lib/python3.12/site-packages/celery/bootsteps.py", line 116, in start
    step.start(parent)
  File "/Library/Frameworks/Python.framework/Versions/3.12/lib/python3.12/site-packages/celery/bootsteps.py", line 365, in start
    return self.obj.start()
           ^^^^^^^^^^^^^^^^
  File "/Library/Frameworks/Python.framework/Versions/3.12/lib/python3.12/site-packages/celery/worker/consumer/consumer.py", line 340, in start
    blueprint.start(self)
  File "/Library/Frameworks/Python.framework/Versions/3.12/lib/python3.12/site-packages/celery/bootsteps.py", line 116, in start
    step.start(parent)
  File "/Library/Frameworks/Python.framework/Versions/3.12/lib/python3.12/site-packages/celery/worker/consumer/consumer.py", line 742, in start
    c.loop(*c.loop_args())
  File "/Library/Frameworks/Python.framework/Versions/3.12/lib/python3.12/site-packages/celery/worker/loops.py", line 86, in asynloop
    state.maybe_shutdown()
  File "/Library/Frameworks/Python.framework/Versions/3.12/lib/python3.12/site-packages/celery/worker/state.py", line 93, in maybe_shutdown
    raise WorkerShutdown(should_stop)
celery.exceptions.WorkerShutdown: 0

During handling of the above exception, another exception occurred:

Traceback (most recent call last):
  File "/Library/Frameworks/Python.framework/Versions/3.12/lib/python3.12/site-packages/billiard/pool.py", line 1265, in mark_as_worker_lost
    raise WorkerLostError(
billiard.exceptions.WorkerLostError: Worker exited prematurely: signal 15 (SIGTERM) Job: 1.
"""
[2025-10-12 11:26:12] ERROR    [celery.worker.request:643] [MainProcess] Task handler raised error: WorkerLostError('Worker exited prematurely: signal 15 (SIGTERM) Job: 1.')
Traceback (most recent call last):
  File "/Library/Frameworks/Python.framework/Versions/3.12/lib/python3.12/site-packages/billiard/pool.py", line 1265, in mark_as_worker_lost
    raise WorkerLostError(
billiard.einfo.ExceptionWithTraceback: 
"""
Traceback (most recent call last):
  File "/Library/Frameworks/Python.framework/Versions/3.12/lib/python3.12/site-packages/celery/worker/worker.py", line 202, in start
    self.blueprint.start(self)
  File "/Library/Frameworks/Python.framework/Versions/3.12/lib/python3.12/site-packages/celery/bootsteps.py", line 116, in start
    step.start(parent)
  File "/Library/Frameworks/Python.framework/Versions/3.12/lib/python3.12/site-packages/celery/bootsteps.py", line 365, in start
    return self.obj.start()
           ^^^^^^^^^^^^^^^^
  File "/Library/Frameworks/Python.framework/Versions/3.12/lib/python3.12/site-packages/celery/worker/consumer/consumer.py", line 340, in start
    blueprint.start(self)
  File "/Library/Frameworks/Python.framework/Versions/3.12/lib/python3.12/site-packages/celery/bootsteps.py", line 116, in start
    step.start(parent)
  File "/Library/Frameworks/Python.framework/Versions/3.12/lib/python3.12/site-packages/celery/worker/consumer/consumer.py", line 742, in start
    c.loop(*c.loop_args())
  File "/Library/Frameworks/Python.framework/Versions/3.12/lib/python3.12/site-packages/celery/worker/loops.py", line 86, in asynloop
    state.maybe_shutdown()
  File "/Library/Frameworks/Python.framework/Versions/3.12/lib/python3.12/site-packages/celery/worker/state.py", line 93, in maybe_shutdown
    raise WorkerShutdown(should_stop)
celery.exceptions.WorkerShutdown: 0

During handling of the above exception, another exception occurred:

Traceback (most recent call last):
  File "/Library/Frameworks/Python.framework/Versions/3.12/lib/python3.12/site-packages/billiard/pool.py", line 1265, in mark_as_worker_lost
    raise WorkerLostError(
billiard.exceptions.WorkerLostError: Worker exited prematurely: signal 15 (SIGTERM) Job: 1.
"""
[2025-10-12 11:36:39] ERROR    [celery.worker.request:643] [MainProcess] Task handler raised error: WorkerLostError('Worker exited prematurely: signal 15 (SIGTERM) Job: 1.')
Traceback (most recent call last):
  File "/Library/Frameworks/Python.framework/Versions/3.12/lib/python3.12/site-packages/billiard/pool.py", line 1265, in mark_as_worker_lost
    raise WorkerLostError(
billiard.einfo.ExceptionWithTraceback: 
"""
Traceback (most recent call last):
  File "/Library/Frameworks/Python.framework/Versions/3.12/lib/python3.12/site-packages/celery/worker/worker.py", line 202, in start
    self.blueprint.start(self)
  File "/Library/Frameworks/Python.framework/Versions/3.12/lib/python3.12/site-packages/celery/bootsteps.py", line 116, in start
    step.start(parent)
  File "/Library/Frameworks/Python.framework/Versions/3.12/lib/python3.12/site-packages/celery/bootsteps.py", line 365, in start
    return self.obj.start()
           ^^^^^^^^^^^^^^^^
  File "/Library/Frameworks/Python.framework/Versions/3.12/lib/python3.12/site-packages/celery/worker/consumer/consumer.py", line 340, in start
    blueprint.start(self)
  File "/Library/Frameworks/Python.framework/Versions/3.12/lib/python3.12/site-packages/celery/bootsteps.py", line 116, in start
    step.start(parent)
  File "/Library/Frameworks/Python.framework/Versions/3.12/lib/python3.12/site-packages/celery/worker/consumer/consumer.py", line 742, in start
    c.loop(*c.loop_args())
  File "/Library/Frameworks/Python.framework/Versions/3.12/lib/python3.12/site-packages/celery/worker/loops.py", line 86, in asynloop
    state.maybe_shutdown()
  File "/Library/Frameworks/Python.framework/Versions/3.12/lib/python3.12/site-packages/celery/worker/state.py", line 93, in maybe_shutdown
    raise WorkerShutdown(should_stop)
celery.exceptions.WorkerShutdown: 0

During handling of the above exception, another exception occurred:

Traceback (most recent call last):
  File "/Library/Frameworks/Python.framework/Versions/3.12/lib/python3.12/site-packages/billiard/pool.py", line 1265, in mark_as_worker_lost
    raise WorkerLostError(
billiard.exceptions.WorkerLostError: Worker exited prematurely: signal 15 (SIGTERM) Job: 1.
"""
[2025-10-12 12:06:02] ERROR    [celery.worker.request:643] [MainProcess] Task handler raised error: WorkerLostError('Worker exited prematurely: signal 15 (SIGTERM) Job: 1.')
Traceback (most recent call last):
  File "/Library/Frameworks/Python.framework/Versions/3.12/lib/python3.12/site-packages/billiard/pool.py", line 1265, in mark_as_worker_lost
    raise WorkerLostError(
billiard.einfo.ExceptionWithTraceback: 
"""
Traceback (most recent call last):
  File "/Library/Frameworks/Python.framework/Versions/3.12/lib/python3.12/site-packages/celery/worker/worker.py", line 202, in start
    self.blueprint.start(self)
  File "/Library/Frameworks/Python.framework/Versions/3.12/lib/python3.12/site-packages/celery/bootsteps.py", line 116, in start
    step.start(parent)
  File "/Library/Frameworks/Python.framework/Versions/3.12/lib/python3.12/site-packages/celery/bootsteps.py", line 365, in start
    return self.obj.start()
           ^^^^^^^^^^^^^^^^
  File "/Library/Frameworks/Python.framework/Versions/3.12/lib/python3.12/site-packages/celery/worker/consumer/consumer.py", line 340, in start
    blueprint.start(self)
  File "/Library/Frameworks/Python.framework/Versions/3.12/lib/python3.12/site-packages/celery/bootsteps.py", line 116, in start
    step.start(parent)
  File "/Library/Frameworks/Python.framework/Versions/3.12/lib/python3.12/site-packages/celery/worker/consumer/consumer.py", line 742, in start
    c.loop(*c.loop_args())
  File "/Library/Frameworks/Python.framework/Versions/3.12/lib/python3.12/site-packages/celery/worker/loops.py", line 86, in asynloop
    state.maybe_shutdown()
  File "/Library/Frameworks/Python.framework/Versions/3.12/lib/python3.12/site-packages/celery/worker/state.py", line 93, in maybe_shutdown
    raise WorkerShutdown(should_stop)
celery.exceptions.WorkerShutdown: 0

During handling of the above exception, another exception occurred:

Traceback (most recent call last):
  File "/Library/Frameworks/Python.framework/Versions/3.12/lib/python3.12/site-packages/billiard/pool.py", line 1265, in mark_as_worker_lost
    raise WorkerLostError(
billiard.exceptions.WorkerLostError: Worker exited prematurely: signal 15 (SIGTERM) Job: 1.
"""
[2025-10-12 12:15:13] ERROR    [celery.worker.request:643] [MainProcess] Task handler raised error: WorkerLostError('Worker exited prematurely: signal 15 (SIGTERM) Job: 1.')
Traceback (most recent call last):
  File "/Library/Frameworks/Python.framework/Versions/3.12/lib/python3.12/site-packages/billiard/pool.py", line 1265, in mark_as_worker_lost
    raise WorkerLostError(
billiard.einfo.ExceptionWithTraceback: 
"""
Traceback (most recent call last):
  File "/Library/Frameworks/Python.framework/Versions/3.12/lib/python3.12/site-packages/celery/worker/worker.py", line 202, in start
    self.blueprint.start(self)
  File "/Library/Frameworks/Python.framework/Versions/3.12/lib/python3.12/site-packages/celery/bootsteps.py", line 116, in start
    step.start(parent)
  File "/Library/Frameworks/Python.framework/Versions/3.12/lib/python3.12/site-packages/celery/bootsteps.py", line 365, in start
    return self.obj.start()
           ^^^^^^^^^^^^^^^^
  File "/Library/Frameworks/Python.framework/Versions/3.12/lib/python3.12/site-packages/celery/worker/consumer/consumer.py", line 340, in start
    blueprint.start(self)
  File "/Library/Frameworks/Python.framework/Versions/3.12/lib/python3.12/site-packages/celery/bootsteps.py", line 116, in start
    step.start(parent)
  File "/Library/Frameworks/Python.framework/Versions/3.12/lib/python3.12/site-packages/celery/worker/consumer/consumer.py", line 742, in start
    c.loop(*c.loop_args())
  File "/Library/Frameworks/Python.framework/Versions/3.12/lib/python3.12/site-packages/celery/worker/loops.py", line 86, in asynloop
    state.maybe_shutdown()
  File "/Library/Frameworks/Python.framework/Versions/3.12/lib/python3.12/site-packages/celery/worker/state.py", line 93, in maybe_shutdown
    raise WorkerShutdown(should_stop)
celery.exceptions.WorkerShutdown: 0

During handling of the above exception, another exception occurred:

Traceback (most recent call last):
  File "/Library/Frameworks/Python.framework/Versions/3.12/lib/python3.12/site-packages/billiard/pool.py", line 1265, in mark_as_worker_lost
    raise WorkerLostError(
billiard.exceptions.WorkerLostError: Worker exited prematurely: signal 15 (SIGTERM) Job: 1.
"""
[2025-10-12 12:27:39] ERROR    [celery.worker.request:643] [MainProcess] Task handler raised error: WorkerLostError('Worker exited prematurely: signal 15 (SIGTERM) Job: 1.')
Traceback (most recent call last):
  File "/Library/Frameworks/Python.framework/Versions/3.12/lib/python3.12/site-packages/billiard/pool.py", line 1265, in mark_as_worker_lost
    raise WorkerLostError(
billiard.einfo.ExceptionWithTraceback: 
"""
Traceback (most recent call last):
  File "/Library/Frameworks/Python.framework/Versions/3.12/lib/python3.12/site-packages/celery/worker/worker.py", line 202, in start
    self.blueprint.start(self)
  File "/Library/Frameworks/Python.framework/Versions/3.12/lib/python3.12/site-packages/celery/bootsteps.py", line 116, in start
    step.start(parent)
  File "/Library/Frameworks/Python.framework/Versions/3.12/lib/python3.12/site-packages/celery/bootsteps.py", line 365, in start
    return self.obj.start()
           ^^^^^^^^^^^^^^^^
  File "/Library/Frameworks/Python.framework/Versions/3.12/lib/python3.12/site-packages/celery/worker/consumer/consumer.py", line 340, in start
    blueprint.start(self)
  File "/Library/Frameworks/Python.framework/Versions/3.12/lib/python3.12/site-packages/celery/bootsteps.py", line 116, in start
    step.start(parent)
  File "/Library/Frameworks/Python.framework/Versions/3.12/lib/python3.12/site-packages/celery/worker/consumer/consumer.py", line 742, in start
    c.loop(*c.loop_args())
  File "/Library/Frameworks/Python.framework/Versions/3.12/lib/python3.12/site-packages/celery/worker/loops.py", line 86, in asynloop
    state.maybe_shutdown()
  File "/Library/Frameworks/Python.framework/Versions/3.12/lib/python3.12/site-packages/celery/worker/state.py", line 93, in maybe_shutdown
    raise WorkerShutdown(should_stop)
celery.exceptions.WorkerShutdown: 0

During handling of the above exception, another exception occurred:

Traceback (most recent call last):
  File "/Library/Frameworks/Python.framework/Versions/3.12/lib/python3.12/site-packages/billiard/pool.py", line 1265, in mark_as_worker_lost
    raise WorkerLostError(
billiard.exceptions.WorkerLostError: Worker exited prematurely: signal 15 (SIGTERM) Job: 1.
"""
[2025-10-12 12:37:13] ERROR    [celery.worker.request:643] [MainProcess] Task handler raised error: WorkerLostError('Worker exited prematurely: signal 15 (SIGTERM) Job: 1.')
Traceback (most recent call last):
  File "/Library/Frameworks/Python.framework/Versions/3.12/lib/python3.12/site-packages/billiard/pool.py", line 1265, in mark_as_worker_lost
    raise WorkerLostError(
billiard.einfo.ExceptionWithTraceback: 
"""
Traceback (most recent call last):
  File "/Library/Frameworks/Python.framework/Versions/3.12/lib/python3.12/site-packages/celery/worker/worker.py", line 202, in start
    self.blueprint.start(self)
  File "/Library/Frameworks/Python.framework/Versions/3.12/lib/python3.12/site-packages/celery/bootsteps.py", line 116, in start
    step.start(parent)
  File "/Library/Frameworks/Python.framework/Versions/3.12/lib/python3.12/site-packages/celery/bootsteps.py", line 365, in start
    return self.obj.start()
           ^^^^^^^^^^^^^^^^
  File "/Library/Frameworks/Python.framework/Versions/3.12/lib/python3.12/site-packages/celery/worker/consumer/consumer.py", line 340, in start
    blueprint.start(self)
  File "/Library/Frameworks/Python.framework/Versions/3.12/lib/python3.12/site-packages/celery/bootsteps.py", line 116, in start
    step.start(parent)
  File "/Library/Frameworks/Python.framework/Versions/3.12/lib/python3.12/site-packages/celery/worker/consumer/consumer.py", line 742, in start
    c.loop(*c.loop_args())
  File "/Library/Frameworks/Python.framework/Versions/3.12/lib/python3.12/site-packages/celery/worker/loops.py", line 86, in asynloop
    state.maybe_shutdown()
  File "/Library/Frameworks/Python.framework/Versions/3.12/lib/python3.12/site-packages/celery/worker/state.py", line 93, in maybe_shutdown
    raise WorkerShutdown(should_stop)
celery.exceptions.WorkerShutdown: 0

During handling of the above exception, another exception occurred:

Traceback (most recent call last):
  File "/Library/Frameworks/Python.framework/Versions/3.12/lib/python3.12/site-packages/billiard/pool.py", line 1265, in mark_as_worker_lost
    raise WorkerLostError(
billiard.exceptions.WorkerLostError: Worker exited prematurely: signal 15 (SIGTERM) Job: 1.
"""
[2025-10-12 14:07:41] ERROR    [celery.worker.request:643] [MainProcess] Task handler raised error: WorkerLostError('Worker exited prematurely: signal 15 (SIGTERM) Job: 1.')
Traceback (most recent call last):
  File "/Library/Frameworks/Python.framework/Versions/3.12/lib/python3.12/site-packages/billiard/pool.py", line 1265, in mark_as_worker_lost
    raise WorkerLostError(
billiard.einfo.ExceptionWithTraceback: 
"""
Traceback (most recent call last):
  File "/Library/Frameworks/Python.framework/Versions/3.12/lib/python3.12/site-packages/celery/worker/worker.py", line 202, in start
    self.blueprint.start(self)
  File "/Library/Frameworks/Python.framework/Versions/3.12/lib/python3.12/site-packages/celery/bootsteps.py", line 116, in start
    step.start(parent)
  File "/Library/Frameworks/Python.framework/Versions/3.12/lib/python3.12/site-packages/celery/bootsteps.py", line 365, in start
    return self.obj.start()
           ^^^^^^^^^^^^^^^^
  File "/Library/Frameworks/Python.framework/Versions/3.12/lib/python3.12/site-packages/celery/worker/consumer/consumer.py", line 340, in start
    blueprint.start(self)
  File "/Library/Frameworks/Python.framework/Versions/3.12/lib/python3.12/site-packages/celery/bootsteps.py", line 116, in start
    step.start(parent)
  File "/Library/Frameworks/Python.framework/Versions/3.12/lib/python3.12/site-packages/celery/worker/consumer/consumer.py", line 742, in start
    c.loop(*c.loop_args())
  File "/Library/Frameworks/Python.framework/Versions/3.12/lib/python3.12/site-packages/celery/worker/loops.py", line 86, in asynloop
    state.maybe_shutdown()
  File "/Library/Frameworks/Python.framework/Versions/3.12/lib/python3.12/site-packages/celery/worker/state.py", line 93, in maybe_shutdown
    raise WorkerShutdown(should_stop)
celery.exceptions.WorkerShutdown: 0

During handling of the above exception, another exception occurred:

Traceback (most recent call last):
  File "/Library/Frameworks/Python.framework/Versions/3.12/lib/python3.12/site-packages/billiard/pool.py", line 1265, in mark_as_worker_lost
    raise WorkerLostError(
billiard.exceptions.WorkerLostError: Worker exited prematurely: signal 15 (SIGTERM) Job: 1.
"""
[2025-10-12 14:11:51] ERROR    [celery.worker.request:643] [MainProcess] Task handler raised error: WorkerLostError('Worker exited prematurely: signal 15 (SIGTERM) Job: 1.')
Traceback (most recent call last):
  File "/Library/Frameworks/Python.framework/Versions/3.12/lib/python3.12/site-packages/billiard/pool.py", line 1265, in mark_as_worker_lost
    raise WorkerLostError(
billiard.einfo.ExceptionWithTraceback: 
"""
Traceback (most recent call last):
  File "/Library/Frameworks/Python.framework/Versions/3.12/lib/python3.12/site-packages/celery/worker/worker.py", line 202, in start
    self.blueprint.start(self)
  File "/Library/Frameworks/Python.framework/Versions/3.12/lib/python3.12/site-packages/celery/bootsteps.py", line 116, in start
    step.start(parent)
  File "/Library/Frameworks/Python.framework/Versions/3.12/lib/python3.12/site-packages/celery/bootsteps.py", line 365, in start
    return self.obj.start()
           ^^^^^^^^^^^^^^^^
  File "/Library/Frameworks/Python.framework/Versions/3.12/lib/python3.12/site-packages/celery/worker/consumer/consumer.py", line 340, in start
    blueprint.start(self)
  File "/Library/Frameworks/Python.framework/Versions/3.12/lib/python3.12/site-packages/celery/bootsteps.py", line 116, in start
    step.start(parent)
  File "/Library/Frameworks/Python.framework/Versions/3.12/lib/python3.12/site-packages/celery/worker/consumer/consumer.py", line 742, in start
    c.loop(*c.loop_args())
  File "/Library/Frameworks/Python.framework/Versions/3.12/lib/python3.12/site-packages/celery/worker/loops.py", line 86, in asynloop
    state.maybe_shutdown()
  File "/Library/Frameworks/Python.framework/Versions/3.12/lib/python3.12/site-packages/celery/worker/state.py", line 93, in maybe_shutdown
    raise WorkerShutdown(should_stop)
celery.exceptions.WorkerShutdown: 0

During handling of the above exception, another exception occurred:

Traceback (most recent call last):
  File "/Library/Frameworks/Python.framework/Versions/3.12/lib/python3.12/site-packages/billiard/pool.py", line 1265, in mark_as_worker_lost
    raise WorkerLostError(
billiard.exceptions.WorkerLostError: Worker exited prematurely: signal 15 (SIGTERM) Job: 1.
"""
[2025-10-12 14:30:05] ERROR    [celery.worker.request:643] [MainProcess] Task handler raised error: WorkerLostError('Worker exited prematurely: signal 15 (SIGTERM) Job: 1.')
Traceback (most recent call last):
  File "/Library/Frameworks/Python.framework/Versions/3.12/lib/python3.12/site-packages/billiard/pool.py", line 1265, in mark_as_worker_lost
    raise WorkerLostError(
billiard.einfo.ExceptionWithTraceback: 
"""
Traceback (most recent call last):
  File "/Library/Frameworks/Python.framework/Versions/3.12/lib/python3.12/site-packages/celery/worker/worker.py", line 202, in start
    self.blueprint.start(self)
  File "/Library/Frameworks/Python.framework/Versions/3.12/lib/python3.12/site-packages/celery/bootsteps.py", line 116, in start
    step.start(parent)
  File "/Library/Frameworks/Python.framework/Versions/3.12/lib/python3.12/site-packages/celery/bootsteps.py", line 365, in start
    return self.obj.start()
           ^^^^^^^^^^^^^^^^
  File "/Library/Frameworks/Python.framework/Versions/3.12/lib/python3.12/site-packages/celery/worker/consumer/consumer.py", line 340, in start
    blueprint.start(self)
  File "/Library/Frameworks/Python.framework/Versions/3.12/lib/python3.12/site-packages/celery/bootsteps.py", line 116, in start
    step.start(parent)
  File "/Library/Frameworks/Python.framework/Versions/3.12/lib/python3.12/site-packages/celery/worker/consumer/consumer.py", line 742, in start
    c.loop(*c.loop_args())
  File "/Library/Frameworks/Python.framework/Versions/3.12/lib/python3.12/site-packages/celery/worker/loops.py", line 86, in asynloop
    state.maybe_shutdown()
  File "/Library/Frameworks/Python.framework/Versions/3.12/lib/python3.12/site-packages/celery/worker/state.py", line 93, in maybe_shutdown
    raise WorkerShutdown(should_stop)
celery.exceptions.WorkerShutdown: 0

During handling of the above exception, another exception occurred:

Traceback (most recent call last):
  File "/Library/Frameworks/Python.framework/Versions/3.12/lib/python3.12/site-packages/billiard/pool.py", line 1265, in mark_as_worker_lost
    raise WorkerLostError(
billiard.exceptions.WorkerLostError: Worker exited prematurely: signal 15 (SIGTERM) Job: 1.
"""
[2025-10-12 15:14:03] ERROR    [celery.worker.request:643] [MainProcess] Task handler raised error: WorkerLostError('Worker exited prematurely: signal 15 (SIGTERM) Job: 1.')
Traceback (most recent call last):
  File "/Library/Frameworks/Python.framework/Versions/3.12/lib/python3.12/site-packages/billiard/pool.py", line 1265, in mark_as_worker_lost
    raise WorkerLostError(
billiard.einfo.ExceptionWithTraceback: 
"""
Traceback (most recent call last):
  File "/Library/Frameworks/Python.framework/Versions/3.12/lib/python3.12/site-packages/celery/worker/worker.py", line 202, in start
    self.blueprint.start(self)
  File "/Library/Frameworks/Python.framework/Versions/3.12/lib/python3.12/site-packages/celery/bootsteps.py", line 116, in start
    step.start(parent)
  File "/Library/Frameworks/Python.framework/Versions/3.12/lib/python3.12/site-packages/celery/bootsteps.py", line 365, in start
    return self.obj.start()
           ^^^^^^^^^^^^^^^^
  File "/Library/Frameworks/Python.framework/Versions/3.12/lib/python3.12/site-packages/celery/worker/consumer/consumer.py", line 340, in start
    blueprint.start(self)
  File "/Library/Frameworks/Python.framework/Versions/3.12/lib/python3.12/site-packages/celery/bootsteps.py", line 116, in start
    step.start(parent)
  File "/Library/Frameworks/Python.framework/Versions/3.12/lib/python3.12/site-packages/celery/worker/consumer/consumer.py", line 742, in start
    c.loop(*c.loop_args())
  File "/Library/Frameworks/Python.framework/Versions/3.12/lib/python3.12/site-packages/celery/worker/loops.py", line 86, in asynloop
    state.maybe_shutdown()
  File "/Library/Frameworks/Python.framework/Versions/3.12/lib/python3.12/site-packages/celery/worker/state.py", line 93, in maybe_shutdown
    raise WorkerShutdown(should_stop)
celery.exceptions.WorkerShutdown: 0

During handling of the above exception, another exception occurred:

Traceback (most recent call last):
  File "/Library/Frameworks/Python.framework/Versions/3.12/lib/python3.12/site-packages/billiard/pool.py", line 1265, in mark_as_worker_lost
    raise WorkerLostError(
billiard.exceptions.WorkerLostError: Worker exited prematurely: signal 15 (SIGTERM) Job: 1.
"""
[2025-10-12 15:21:57] ERROR    [celery.worker.request:643] [MainProcess] Task handler raised error: WorkerLostError('Worker exited prematurely: signal 15 (SIGTERM) Job: 1.')
Traceback (most recent call last):
  File "/Library/Frameworks/Python.framework/Versions/3.12/lib/python3.12/site-packages/billiard/pool.py", line 1265, in mark_as_worker_lost
    raise WorkerLostError(
billiard.einfo.ExceptionWithTraceback: 
"""
Traceback (most recent call last):
  File "/Library/Frameworks/Python.framework/Versions/3.12/lib/python3.12/site-packages/celery/worker/worker.py", line 202, in start
    self.blueprint.start(self)
  File "/Library/Frameworks/Python.framework/Versions/3.12/lib/python3.12/site-packages/celery/bootsteps.py", line 116, in start
    step.start(parent)
  File "/Library/Frameworks/Python.framework/Versions/3.12/lib/python3.12/site-packages/celery/bootsteps.py", line 365, in start
    return self.obj.start()
           ^^^^^^^^^^^^^^^^
  File "/Library/Frameworks/Python.framework/Versions/3.12/lib/python3.12/site-packages/celery/worker/consumer/consumer.py", line 340, in start
    blueprint.start(self)
  File "/Library/Frameworks/Python.framework/Versions/3.12/lib/python3.12/site-packages/celery/bootsteps.py", line 116, in start
    step.start(parent)
  File "/Library/Frameworks/Python.framework/Versions/3.12/lib/python3.12/site-packages/celery/worker/consumer/consumer.py", line 742, in start
    c.loop(*c.loop_args())
  File "/Library/Frameworks/Python.framework/Versions/3.12/lib/python3.12/site-packages/celery/worker/loops.py", line 86, in asynloop
    state.maybe_shutdown()
  File "/Library/Frameworks/Python.framework/Versions/3.12/lib/python3.12/site-packages/celery/worker/state.py", line 93, in maybe_shutdown
    raise WorkerShutdown(should_stop)
celery.exceptions.WorkerShutdown: 0

During handling of the above exception, another exception occurred:

Traceback (most recent call last):
  File "/Library/Frameworks/Python.framework/Versions/3.12/lib/python3.12/site-packages/billiard/pool.py", line 1265, in mark_as_worker_lost
    raise WorkerLostError(
billiard.exceptions.WorkerLostError: Worker exited prematurely: signal 15 (SIGTERM) Job: 1.
"""
[2025-10-19 19:20:38] ERROR    [celery.worker.consumer.consumer:492] [MainProcess] consumer: Cannot connect to amqp://ai_agent_user:**@127.0.0.1:5672/ai_agent: [Errno 54] Connection reset by peer.
Trying again in 2.00 seconds... (1/10)

[2025-10-19 19:20:40] ERROR    [celery.worker.consumer.consumer:492] [MainProcess] consumer: Cannot connect to amqp://ai_agent_user:**@127.0.0.1:5672/ai_agent: [Errno 54] Connection reset by peer.
Trying again in 4.00 seconds... (2/10)

[2025-10-19 19:20:44] ERROR    [celery.worker.consumer.consumer:492] [MainProcess] consumer: Cannot connect to amqp://ai_agent_user:**@127.0.0.1:5672/ai_agent: [Errno 54] Connection reset by peer.
Trying again in 6.00 seconds... (3/10)

[2025-10-19 19:20:50] ERROR    [celery.worker.consumer.consumer:492] [MainProcess] consumer: Cannot connect to amqp://ai_agent_user:**@127.0.0.1:5672/ai_agent: [Errno 61] Connection refused.
Trying again in 8.00 seconds... (4/10)

[2025-10-19 19:20:58] ERROR    [celery.worker.consumer.consumer:492] [MainProcess] consumer: Cannot connect to amqp://ai_agent_user:**@127.0.0.1:5672/ai_agent: [Errno 61] Connection refused.
Trying again in 10.00 seconds... (5/10)

[2025-10-19 19:21:08] ERROR    [celery.worker.consumer.consumer:492] [MainProcess] consumer: Cannot connect to amqp://ai_agent_user:**@127.0.0.1:5672/ai_agent: [Errno 61] Connection refused.
Trying again in 12.00 seconds... (6/10)

[2025-10-19 19:21:21] ERROR    [celery.worker.consumer.consumer:492] [MainProcess] consumer: Cannot connect to amqp://ai_agent_user:**@127.0.0.1:5672/ai_agent: [Errno 61] Connection refused.
Trying again in 14.00 seconds... (7/10)

[2025-10-19 19:21:35] ERROR    [celery.worker.consumer.consumer:492] [MainProcess] consumer: Cannot connect to amqp://ai_agent_user:**@127.0.0.1:5672/ai_agent: [Errno 61] Connection refused.
Trying again in 16.00 seconds... (8/10)

[2025-10-19 19:21:51] ERROR    [celery.worker.consumer.consumer:492] [MainProcess] consumer: Cannot connect to amqp://ai_agent_user:**@127.0.0.1:5672/ai_agent: [Errno 61] Connection refused.
Trying again in 18.00 seconds... (9/10)

[2025-10-19 19:22:09] ERROR    [celery.worker.consumer.consumer:492] [MainProcess] consumer: Cannot connect to amqp://ai_agent_user:**@127.0.0.1:5672/ai_agent: [Errno 61] Connection refused.
Trying again in 20.00 seconds... (10/10)

[2025-10-19 19:22:29] CRITICAL [celery.worker:206] [MainProcess] Unrecoverable error: OperationalError('[Errno 61] Connection refused')
Traceback (most recent call last):
  File "/Library/Frameworks/Python.framework/Versions/3.12/lib/python3.12/site-packages/kombu/connection.py", line 472, in _reraise_as_library_errors
    yield
  File "/Library/Frameworks/Python.framework/Versions/3.12/lib/python3.12/site-packages/kombu/connection.py", line 459, in _ensure_connection
    return retry_over_time(
           ^^^^^^^^^^^^^^^^
  File "/Library/Frameworks/Python.framework/Versions/3.12/lib/python3.12/site-packages/kombu/utils/functional.py", line 318, in retry_over_time
    return fun(*args, **kwargs)
           ^^^^^^^^^^^^^^^^^^^^
  File "/Library/Frameworks/Python.framework/Versions/3.12/lib/python3.12/site-packages/kombu/connection.py", line 934, in _connection_factory
    self._connection = self._establish_connection()
                       ^^^^^^^^^^^^^^^^^^^^^^^^^^^^
  File "/Library/Frameworks/Python.framework/Versions/3.12/lib/python3.12/site-packages/kombu/connection.py", line 860, in _establish_connection
    conn = self.transport.establish_connection()
           ^^^^^^^^^^^^^^^^^^^^^^^^^^^^^^^^^^^^^
  File "/Library/Frameworks/Python.framework/Versions/3.12/lib/python3.12/site-packages/kombu/transport/pyamqp.py", line 203, in establish_connection
    conn.connect()
  File "/Library/Frameworks/Python.framework/Versions/3.12/lib/python3.12/site-packages/amqp/connection.py", line 324, in connect
    self.transport.connect()
  File "/Library/Frameworks/Python.framework/Versions/3.12/lib/python3.12/site-packages/amqp/transport.py", line 129, in connect
    self._connect(self.host, self.port, self.connect_timeout)
  File "/Library/Frameworks/Python.framework/Versions/3.12/lib/python3.12/site-packages/amqp/transport.py", line 184, in _connect
    self.sock.connect(sa)
ConnectionRefusedError: [Errno 61] Connection refused

The above exception was the direct cause of the following exception:

Traceback (most recent call last):
  File "/Library/Frameworks/Python.framework/Versions/3.12/lib/python3.12/site-packages/celery/worker/worker.py", line 202, in start
    self.blueprint.start(self)
  File "/Library/Frameworks/Python.framework/Versions/3.12/lib/python3.12/site-packages/celery/bootsteps.py", line 116, in start
    step.start(parent)
  File "/Library/Frameworks/Python.framework/Versions/3.12/lib/python3.12/site-packages/celery/bootsteps.py", line 365, in start
    return self.obj.start()
           ^^^^^^^^^^^^^^^^
  File "/Library/Frameworks/Python.framework/Versions/3.12/lib/python3.12/site-packages/celery/worker/consumer/consumer.py", line 340, in start
    blueprint.start(self)
  File "/Library/Frameworks/Python.framework/Versions/3.12/lib/python3.12/site-packages/celery/bootsteps.py", line 116, in start
    step.start(parent)
  File "/Library/Frameworks/Python.framework/Versions/3.12/lib/python3.12/site-packages/celery/worker/consumer/connection.py", line 21, in start
    c.connection = c.connect()
                   ^^^^^^^^^^^
  File "/Library/Frameworks/Python.framework/Versions/3.12/lib/python3.12/site-packages/celery/worker/consumer/consumer.py", line 469, in connect
    conn = self.connection_for_read(heartbeat=self.amqheartbeat)
           ^^^^^^^^^^^^^^^^^^^^^^^^^^^^^^^^^^^^^^^^^^^^^^^^^^^^^
  File "/Library/Frameworks/Python.framework/Versions/3.12/lib/python3.12/site-packages/celery/worker/consumer/consumer.py", line 475, in connection_for_read
    return self.ensure_connected(
           ^^^^^^^^^^^^^^^^^^^^^^
  File "/Library/Frameworks/Python.framework/Versions/3.12/lib/python3.12/site-packages/celery/worker/consumer/consumer.py", line 526, in ensure_connected
    conn = conn.ensure_connection(
           ^^^^^^^^^^^^^^^^^^^^^^^
  File "/Library/Frameworks/Python.framework/Versions/3.12/lib/python3.12/site-packages/kombu/connection.py", line 406, in ensure_connection
    self._ensure_connection(*args, **kwargs)
  File "/Library/Frameworks/Python.framework/Versions/3.12/lib/python3.12/site-packages/kombu/connection.py", line 458, in _ensure_connection
    with ctx():
  File "/Library/Frameworks/Python.framework/Versions/3.12/lib/python3.12/contextlib.py", line 155, in __exit__
    self.gen.throw(value)
  File "/Library/Frameworks/Python.framework/Versions/3.12/lib/python3.12/site-packages/kombu/connection.py", line 476, in _reraise_as_library_errors
    raise ConnectionError(str(exc)) from exc
kombu.exceptions.OperationalError: [Errno 61] Connection refused
