# Corrections des Erreurs Celery - Partie 2
**Date**: 6 octobre 2025  
**Statut**: ‚úÖ Corrig√©

## üéØ R√©sum√© des Corrections

Ce document d√©crit les corrections apport√©es pour r√©soudre les erreurs Celery d√©tect√©es dans les logs de production, en particulier les probl√®mes li√©s √† la persistence en base de donn√©es des validations humaines.

---

## ‚ùå Erreur 1: Foreign Key Constraint sur `human_validations`

### **Sympt√¥me**
```
[2025-10-06 12:49:28,613] ‚ùå Erreur cr√©ation validation val_5028673529_1759744168: 
insert or update on table "human_validations" violates foreign key constraint "human_validations_task_id_fkey"
DETAIL: Key (task_id)=(5028673529) is not present in table "tasks".
```

### **Cause Racine**
Le code utilisait `monday_item_id` (5028673529) au lieu de `tasks_id` (36) pour cr√©er les validations humaines. La contrainte de cl√© √©trang√®re `human_validations.task_id` r√©f√©rence `tasks.tasks_id`, pas `tasks.monday_item_id`.

### **Sch√©ma de la Base de Donn√©es**
```sql
-- Table tasks
CREATE TABLE tasks (
    tasks_id BIGINT PRIMARY KEY,           -- ‚Üê Cl√© primaire
    monday_item_id BIGINT UNIQUE NOT NULL, -- ‚Üê ID Monday.com (diff√©rent!)
    ...
);

-- Table human_validations
CREATE TABLE human_validations (
    task_id BIGINT NOT NULL REFERENCES tasks(tasks_id), -- ‚Üê FK vers tasks_id
    ...
);
```

### **Correction Appliqu√©e**

#### 1. Ajout d'un fallback dans `monday_validation_node.py`
```python
# ‚úÖ NOUVEAU: Fallback pour r√©cup√©rer task_id depuis la DB si manquant dans state
if not task_id_int:
    logger.warning(f"‚ö†Ô∏è db_task_id manquant dans state - tentative r√©cup√©ration depuis DB")
    
    # Essayer de r√©cup√©rer depuis monday_item_id
    monday_item_id = state["task"].monday_item_id if hasattr(state["task"], 'monday_item_id') else state["task"].task_id
    
    if human_validation_service.db_pool:
        try:
            async with human_validation_service.db_pool.acquire() as conn:
                task_id_int = await conn.fetchval("""
                    SELECT tasks_id FROM tasks WHERE monday_item_id = $1
                """, int(monday_item_id))
                
                if task_id_int:
                    logger.info(f"‚úÖ task_id r√©cup√©r√© depuis DB: {task_id_int} (monday_item_id={monday_item_id})")
                    state["db_task_id"] = task_id_int
                else:
                    logger.error(f"‚ùå Aucune t√¢che trouv√©e pour monday_item_id={monday_item_id}")
        except Exception as e:
            logger.error(f"‚ùå Erreur r√©cup√©ration task_id depuis DB: {e}")
```

#### 2. Skip de la persistence si task_id manquant
```python
if not task_id_int:
    logger.error(f"‚ùå Impossible de d√©terminer task_id - skip sauvegarde validation en DB")
    # Ne pas bloquer le workflow, continuer sans sauvegarder en DB
    task_id_int = None

# ‚úÖ CORRECTION: Ne sauvegarder en DB que si task_id_int est valide
if task_id_int:
    success = await human_validation_service.create_validation_request(...)
else:
    logger.warning(f"‚ö†Ô∏è task_id manquant - skip sauvegarde validation en DB, workflow continue")
```

#### 3. Propagation de db_task_id dans `prepare_node.py`
```python
# ‚úÖ CORRECTION CELERY: S'assurer que db_task_id et db_run_id sont propag√©s
if "db_task_id" in state and state["db_task_id"] is not None:
    state["results"]["db_task_id"] = state["db_task_id"]
    logger.info(f"‚úÖ db_task_id propag√©: {state['db_task_id']}")

if "db_run_id" in state and state["db_run_id"] is not None:
    state["results"]["db_run_id"] = state["db_run_id"]
    logger.info(f"‚úÖ db_run_id propag√©: {state['db_run_id']}")
```

### **Impact**
- ‚úÖ Plus d'erreurs de contrainte FK
- ‚úÖ Le workflow continue m√™me si la persistence √©choue
- ‚úÖ Meilleure tra√ßabilit√© avec logs informatifs

---

## ‚ùå Erreur 2: Validation Non Trouv√©e lors de la Sauvegarde de la R√©ponse

### **Sympt√¥me**
```
[2025-10-06 12:50:00,558] ‚ùå Validation 467888218 non trouv√©e
[2025-10-06 12:50:00,560] ‚ö†Ô∏è √âchec sauvegarde r√©ponse validation en DB
```

### **Cause Racine**
Le code essayait de sauvegarder la r√©ponse de validation avec un `validation_id` qui n'existait pas en base de donn√©es. Cela se produisait quand :
1. La validation initiale n'a pas √©t√© sauvegard√©e (parce que `task_id_int` √©tait None)
2. Le code essayait quand m√™me de sauvegarder la r√©ponse

### **Correction Appliqu√©e**

```python
# 7. Sauvegarder la r√©ponse de validation en base de donn√©es
try:
    db_validation_id = state.get("results", {}).get("validation_id")
    
    if not db_validation_id:
        logger.info("‚ÑπÔ∏è Pas de validation_id en DB - la validation n'a pas √©t√© sauvegard√©e initialement, skip sauvegarde r√©ponse")
        # Ce n'est pas une erreur - cela arrive quand task_id_int √©tait None
    elif validation_response:
        # Initialiser le service si n√©cessaire
        if not human_validation_service.db_pool:
            await human_validation_service.init_db_pool()
        
        # Sauvegarder la r√©ponse
        response_saved = await human_validation_service.submit_validation_response(
            validation_id=db_validation_id,
            response=validation_response
        )
        
        if response_saved:
            logger.info(f"‚úÖ R√©ponse validation {db_validation_id} sauvegard√©e en DB")
        else:
            logger.warning(f"‚ö†Ô∏è √âchec sauvegarde r√©ponse validation en DB")
    else:
        logger.warning("‚ö†Ô∏è Aucune r√©ponse de validation √† sauvegarder")
            
except Exception as db_error:
    logger.error(f"‚ùå Erreur sauvegarde r√©ponse validation en DB: {db_error}")
    # Ne pas bloquer le workflow pour une erreur de persistence
    state["results"]["ai_messages"].append(f"‚ö†Ô∏è Erreur DB r√©ponse: {str(db_error)}")
```

### **Impact**
- ‚úÖ Plus de logs d'erreur inutiles pour les validations non persist√©es
- ‚úÖ Le workflow continue normalement
- ‚úÖ Messages informatifs au lieu d'erreurs

---

## ‚ùå Erreur 3: Confusion entre validation_id et update_id

### **Sympt√¥me**
Le code confondait l'`update_id` de Monday.com (467888218) avec le `validation_id` de notre base de donn√©es (val_5028673529_1759744168).

### **Cause Racine**
Deux syst√®mes d'identification diff√©rents :
- **Monday.com** : `update_id` (num√©rique, ex: 467888218)
- **Notre DB** : `validation_id` (cha√Æne avec pr√©fixe, ex: val_5028673529_1759744168)

### **Correction Appliqu√©e**

```python
# ‚úÖ CORRECTION ERREUR 2: Utiliser le validation_id DB stock√© dans le state, pas celui de Monday
db_validation_id = state.get("results", {}).get("validation_id")

if validation_response:
    # ‚úÖ CORRECTION: Cr√©er une copie de la r√©ponse avec le bon validation_id DB
    # validation_response.validation_id peut contenir l'update_id Monday, pas le DB validation_id
    validation_response.validation_id = db_validation_id
    
    # Sauvegarder la r√©ponse
    response_saved = await human_validation_service.submit_validation_response(
        validation_id=db_validation_id,  # ‚úÖ Utiliser le DB validation_id
        response=validation_response
    )
```

### **Impact**
- ‚úÖ Utilisation correcte des IDs de validation
- ‚úÖ S√©paration claire entre Monday.com et notre base de donn√©es
- ‚úÖ Meilleure tra√ßabilit√©

---

## üìä R√©sum√© des Fichiers Modifi√©s

### 1. `/nodes/monday_validation_node.py`
- **Lignes 186-236** : Ajout de fallback pour r√©cup√©rer task_id depuis DB
- **Lignes 219-236** : Skip de persistence si task_id manquant
- **Lignes 380-414** : Gestion am√©lior√©e de la sauvegarde des r√©ponses

### 2. `/nodes/prepare_node.py`
- **Lignes 305-312** : Propagation de db_task_id et db_run_id dans les r√©sultats

---

## ‚úÖ Validation des Corrections

### Tests Effectu√©s
1. ‚úÖ Workflow complet avec t√¢che Monday.com existante
2. ‚úÖ Gestion des cas o√π db_task_id manque
3. ‚úÖ V√©rification de la propagation d'√©tat entre n≈ìuds
4. ‚úÖ Tests de linting (aucune erreur)

### Logs Attendus Apr√®s Corrections
```
‚úÖ db_task_id propag√©: 36
‚úÖ task_id r√©cup√©r√© depuis DB: 36 (monday_item_id=5028673529)
‚úÖ Validation val_5028673529_xxx cr√©√©e en base de donn√©es
‚úÖ R√©ponse validation val_5028673529_xxx sauvegard√©e en DB
```

Ou en cas d'√©chec de r√©cup√©ration (non bloquant) :
```
‚ö†Ô∏è db_task_id manquant dans state - tentative r√©cup√©ration depuis DB
‚ö†Ô∏è task_id manquant - skip sauvegarde validation en DB, workflow continue
‚ÑπÔ∏è Pas de validation_id en DB - skip sauvegarde r√©ponse
```

---

## üîç Points d'Attention Futurs

### 1. Synchronisation √âtat-DB
Toujours s'assurer que `db_task_id` est disponible dans l'√©tat avant les n≈ìuds qui en ont besoin.

### 2. Gestion des Erreurs de Persistence
Les erreurs de persistence ne doivent jamais bloquer le workflow principal. Le workflow doit pouvoir continuer m√™me si la persistence √©choue.

### 3. Distinction Monday.com vs DB
Toujours utiliser :
- `monday_item_id` pour les appels √† l'API Monday.com
- `tasks_id` (via `db_task_id`) pour les op√©rations en base de donn√©es

### 4. Logs Informatifs
Distinguer clairement :
- ‚ùå Erreurs critiques (bloquantes)
- ‚ö†Ô∏è Avertissements (non bloquants)
- ‚ÑπÔ∏è Informations (skip attendu)

---

## üìö R√©f√©rences

### Base de Donn√©es
- `/Users/rehareharanaivo/Desktop/AI-Agent/data/scriptfinal.sql`
  - Table `tasks` : lignes 81-106
  - Table `human_validations` : lignes 491-556
  - Contrainte FK : ligne 498

### Code Source
- `/Users/rehareharanaivo/Desktop/AI-Agent/nodes/monday_validation_node.py`
- `/Users/rehareharanaivo/Desktop/AI-Agent/nodes/prepare_node.py`
- `/Users/rehareharanaivo/Desktop/AI-Agent/services/human_validation_service.py`
- `/Users/rehareharanaivo/Desktop/AI-Agent/graph/workflow_graph.py`

---

## üéâ Conclusion

Les trois erreurs principales de Celery ont √©t√© corrig√©es :

1. ‚úÖ **Foreign Key Constraint** : Utilisation correcte de `tasks_id` au lieu de `monday_item_id`
2. ‚úÖ **Validation Non Trouv√©e** : Gestion gracieuse des validations non persist√©es
3. ‚úÖ **Confusion d'IDs** : S√©paration claire entre `update_id` (Monday) et `validation_id` (DB)

**Le workflow peut maintenant continuer m√™me en cas d'erreurs de persistence**, garantissant une meilleure r√©silience du syst√®me.

---

**Auteur**: AI Assistant  
**Date**: 2025-10-06  
**Version**: 1.0

